Workbook

Sheet Sheet1
A5: KECAMATAN | B5: PARTNER | C5: REVENUE MTD | D5: REVENUE LMTD | E5: GROWTH | F5: PRIMARY MTD | G5: PRIMARY LMTD | H5: GROWTH | I5: SECONDARY MTD | J5: SECONDARY LMTD | K5: GROWTH | L5: TERTIARY B# MTD | M5: TERTIARY B# LMTD | N5: GROWTH | O5: TRADE SUPPLY MTD | P5: TRADE SUPPLY LMTD | Q5: GROWTH | R5: VLR SUBS MTD | S5: VLR SUBS LMTD | T5: GROWTH | U5: RGUGA TRADE MTD | V5: RGUGA TRADE LMTD | W5: GROWTH
A6: BENGKAYANG|BENGKAYANG | B6: SDP JAGOI BABANG | C6: =IFERROR(VLOOKUP($A:$A,MASTER!$A:$T,3,0),0) -> 2.0896205e+08 | D6: =IFERROR(VLOOKUP($A:$A,MASTER!$A:$T,4,0),0) -> 2.0071007e+08 | E6: =IFERROR(C6/D6-1,0) -> 0.041113933 | F6: =IFERROR(VLOOKUP(A:A,MASTER!A:E,5,0),0) -> 418468.47 | G6: =IFERROR(VLOOKUP(A:A,MASTER!A:F,6,0),0) -> 1239639.6 | H6: =IFERROR(F6/G6-1,0) -> -0.66242733 | I6: =IFERROR(VLOOKUP(A:A,MASTER!A:M,13,0),0) -> 17877568 | J6: =IFERROR(VLOOKUP($A:$A,MASTER!$A:$T,14,0),0) -> 25190000 | K6: =IFERROR(I6/J6-1,0) -> -0.29029109 | L6: =IFERROR(VLOOKUP($A:$A,MASTER!$A:$T,15,0),0) -> 99988784 | M6: =IFERROR(VLOOKUP($A:$A,MASTER!$A:$T,16,0),0) -> 96201414 | N6: =IFERROR(L6/M6-1,0) -> 0.039369165 | O6: =IFERROR(VLOOKUP($A:$A,MASTER!$A:$T,17,0),0) -> 18706667 | P6: =IFERROR(VLOOKUP($A:$A,MASTER!$A:$T,18,0),0) -> 22817658 | Q6: =IFERROR(O6/P6-1,0) -> -0.18016709 | R6: =IFERROR(VLOOKUP($A:$A,MASTER!$A:$T,19,0),0) -> 8150 | S6: =IFERROR(VLOOKUP($A:$A,MASTER!$A:$T,20,0),0) -> 8094 | T6: =IFERROR(R6/S6-1,0) -> 0.0069187052 | U6: =IFERROR(VLOOKUP(A:A,MASTER!A:K,11,0),0) -> 354 | V6: =IFERROR(VLOOKUP(A:A,MASTER!A:L,12,0),0) -> 135 | W6: =IFERROR(U6/V6-1,0) -> 1.6222222
A7: CAPKALA|BENGKAYANG | B7: SDP MONTERADO | C7: =IFERROR(VLOOKUP($A:$A,MASTER!$A:$T,3,0),0) -> 24968411 | D7: =IFERROR(VLOOKUP($A:$A,MASTER!$A:$T,4,0),0) -> 15542537 | E7: =IFERROR(C7/D7-1,0) -> 0.60645667 | F7: =IFERROR(VLOOKUP(A:A,MASTER!A:E,5,0),0) -> 16216.216 | G7: =IFERROR(VLOOKUP(A:A,MASTER!A:F,6,0),0) -> 40540.541 | H7: =IFERROR(F7/G7-1,0) -> -0.6 | I7: =IFERROR(VLOOKUP(A:A,MASTER!A:M,13,0),0) -> 217567.57 | J7: =IFERROR(VLOOKUP($A:$A,MASTER!$A:$T,14,0),0) -> 40540.541 | K7: =IFERROR(I7/J7-1,0) -> 4.3666667 | L7: =IFERROR(VLOOKUP($A:$A,MASTER!$A:$T,15,0),0) -> 12765721 | M7: =IFERROR(VLOOKUP($A:$A,MASTER!$A:$T,16,0),0) -> 9733333.3 | N7: =IFERROR(L7/M7-1,0) -> 0.31154665 | O7: =IFERROR(VLOOKUP($A:$A,MASTER!$A:$T,17,0),0) -> 201351.35 | P7: =IFERROR(VLOOKUP($A:$A,MASTER!$A:$T,18,0),0) -> 157657.66 | Q7: =IFERROR(O7/P7-1,0) -> 0.27714286 | R7: =IFERROR(VLOOKUP($A:$A,MASTER!$A:$T,19,0),0) -> 1269 | S7: =IFERROR(VLOOKUP($A:$A,MASTER!$A:$T,20,0),0) -> 1327 | T7: =IFERROR(R7/S7-1,0) -> -0.043707611 | U7: =IFERROR(VLOOKUP(A:A,MASTER!A:K,11,0),0) -> 4 | V7: =IFERROR(VLOOKUP(A:A,MASTER!A:L,12,0),0) -> 3 | W7: =IFERROR(U7/V7-1,0) -> 0.33333333
A8: JAGOI BABANG|BENGKAYANG | B8: SDP JAGOI BABANG | C8: =IFERROR(VLOOKUP($A:$A,MASTER!$A:$T,3,0),0) -> 1.5490494e+08 | D8: =IFERROR(VLOOKUP($A:$A,MASTER!$A:$T,4,0),0) -> 1.4925114e+08 | E8: =IFERROR(C8/D8-1,0) -> 0.037881134 | F8: =IFERROR(VLOOKUP(A:A,MASTER!A:E,5,0),0) -> 1519369.4 | G8: =IFERROR(VLOOKUP(A:A,MASTER!A:F,6,0),0) -> 2480180.2 | H8: =IFERROR(F8/G8-1,0) -> -0.38739557 | I8: =IFERROR(VLOOKUP(A:A,MASTER!A:M,13,0),0) -> 30104054 | J8: =IFERROR(VLOOKUP($A:$A,MASTER!$A:$T,14,0),0) -> 21508108 | K8: =IFERROR(I8/J8-1,0) -> 0.39966072 | L8: =IFERROR(VLOOKUP($A:$A,MASTER!$A:$T,15,0),0) -> 39032748 | M8: =IFERROR(VLOOKUP($A:$A,MASTER!$A:$T,16,0),0) -> 43299874 | N8: =IFERROR(L8/M8-1,0) -> -0.098548235 | O8: =IFERROR(VLOOKUP($A:$A,MASTER!$A:$T,17,0),0) -> 30418198 | P8: =IFERROR(VLOOKUP($A:$A,MASTER!$A:$T,18,0),0) -> 21694685 | Q8: =IFERROR(O8/P8-1,0) -> 0.40210372 | R8: =IFERROR(VLOOKUP($A:$A,MASTER!$A:$T,19,0),0) -> 3729 | S8: =IFERROR(VLOOKUP($A:$A,MASTER!$A:$T,20,0),0) -> 3640 | T8: =IFERROR(R8/S8-1,0) -> 0.024450549 | U8: =IFERROR(VLOOKUP(A:A,MASTER!A:K,11,0),0) -> 26 | V8: =IFERROR(VLOOKUP(A:A,MASTER!A:L,12,0),0) -> 26 | W8: =IFERROR(U8/V8-1,0) -> 0
A9: LEDO|BENGKAYANG | B9: SDP JAGOI BABANG | C9: =IFERROR(VLOOKUP($A:$A,MASTER!$A:$T,3,0),0) -> 91334901 | D9: =IFERROR(VLOOKUP($A:$A,MASTER!$A:$T,4,0),0) -> 91172328 | E9: =IFERROR(C9/D9-1,0) -> 0.001783146 | F9: =IFERROR(VLOOKUP(A:A,MASTER!A:E,5,0),0) -> 733333.33 | G9: =IFERROR(VLOOKUP(A:A,MASTER!A:F,6,0),0) -> 854054.05 | H9: =IFERROR(F9/G9-1,0) -> -0.14135021 | I9: =IFERROR(VLOOKUP(A:A,MASTER!A:M,13,0),0) -> 12349099 | J9: =IFERROR(VLOOKUP($A:$A,MASTER!$A:$T,14,0),0) -> 20766667 | K9: =IFERROR(I9/J9-1,0) -> -0.40534033 | L9: =IFERROR(VLOOKUP($A:$A,MASTER!$A:$T,15,0),0) -> 32929685 | M9: =IFERROR(VLOOKUP($A:$A,MASTER!$A:$T,16,0),0) -> 31396369 | N9: =IFERROR(L9/M9-1,0) -> 0.048837345 | O9: =IFERROR(VLOOKUP($A:$A,MASTER!$A:$T,17,0),0) -> 14609279 | P9: =IFERROR(VLOOKUP($A:$A,MASTER!$A:$T,18,0),0) -> 23664324 | Q9: =IFERROR(O9/P9-1,0) -> -0.38264541 | R9: =IFERROR(VLOOKUP($A:$A,MASTER!$A:$T,19,0),0) -> 3476 | S9: =IFERROR(VLOOKUP($A:$A,MASTER!$A:$T,20,0),0) -> 5201 | T9: =IFERROR(R9/S9-1,0) -> -0.33166699 | U9: =IFERROR(VLOOKUP(A:A,MASTER!A:K,11,0),0) -> 8 | V9: =IFERROR(VLOOKUP(A:A,MASTER!A:L,12,0),0) -> 7 | W9: =IFERROR(U9/V9-1,0) -> 0.14285714
A10: LEMBAH BAWANG|BENGKAYANG | B10: SDP MONTERADO | C10: =IFERROR(VLOOKUP($A:$A,MASTER!$A:$T,3,0),0) -> 0 | D10: =IFERROR(VLOOKUP($A:$A,MASTER!$A:$T,4,0),0) -> 0 | E10: =IFERROR(C10/D10-1,0) -> 0 | F10: =IFERROR(VLOOKUP(A:A,MASTER!A:E,5,0),0) -> 1.2192727e+08 | G10: =IFERROR(VLOOKUP(A:A,MASTER!A:F,6,0),0) -> 2.3531109e+08 | H10: =IFERROR(F10/G10-1,0) -> -0.48184649 | I10: =IFERROR(VLOOKUP(A:A,MASTER!A:M,13,0),0) -> 0 | J10: =IFERROR(VLOOKUP($A:$A,MASTER!$A:$T,14,0),0) -> 0 | K10: =IFERROR(I10/J10-1,0) -> 0 | L10: =IFERROR(VLOOKUP($A:$A,MASTER!$A:$T,15,0),0) -> 0 | M10: =IFERROR(VLOOKUP($A:$A,MASTER!$A:$T,16,0),0) -> 0 | N10: =IFERROR(L10/M10-1,0) -> 0 | O10: =IFERROR(VLOOKUP($A:$A,MASTER!$A:$T,17,0),0) -> 0 | P10: =IFERROR(VLOOKUP($A:$A,MASTER!$A:$T,18,0),0) -> 0 | Q10: =IFERROR(O10/P10-1,0) -> 0 | R10: =IFERROR(VLOOKUP($A:$A,MASTER!$A:$T,19,0),0) -> 0 | S10: =IFERROR(VLOOKUP($A:$A,MASTER!$A:$T,20,0),0) -> 0 | T10: =IFERROR(R10/S10-1,0) -> 0 | U10: =IFERROR(VLOOKUP(A:A,MASTER!A:K,11,0),0) -> 0 | V10: =IFERROR(VLOOKUP(A:A,MASTER!A:L,12,0),0) -> 0 | W10: =IFERROR(U10/V10-1,0) -> 0
A11: LUMAR|BENGKAYANG | B11: SDP JAGOI BABANG | C11: =IFERROR(VLOOKUP($A:$A,MASTER!$A:$T,3,0),0) -> 87679462 | D11: =IFERROR(VLOOKUP($A:$A,MASTER!$A:$T,4,0),0) -> 99709795 | E11: =IFERROR(C11/D11-1,0) -> -0.12065348 | F11: =IFERROR(VLOOKUP(A:A,MASTER!A:E,5,0),0) -> 4395045 | G11: =IFERROR(VLOOKUP(A:A,MASTER!A:F,6,0),0) -> 92116216 | H11: =IFERROR(F11/G11-1,0) -> -0.95228804 | I11: =IFERROR(VLOOKUP(A:A,MASTER!A:M,13,0),0) -> 27880360 | J11: =IFERROR(VLOOKUP($A:$A,MASTER!$A:$T,14,0),0) -> 19855405 | K11: =IFERROR(I11/J11-1,0) -> 0.40416979 | L11: =IFERROR(VLOOKUP($A:$A,MASTER!$A:$T,15,0),0) -> 39280180 | M11: =IFERROR(VLOOKUP($A:$A,MASTER!$A:$T,16,0),0) -> 40891541 | N11: =IFERROR(L11/M11-1,0) -> -0.039405714 | O11: =IFERROR(VLOOKUP($A:$A,MASTER!$A:$T,17,0),0) -> 4997027 | P11: =IFERROR(VLOOKUP($A:$A,MASTER!$A:$T,18,0),0) -> 7447567.6 | Q11: =IFERROR(O11/P11-1,0) -> -0.32903905 | R11: =IFERROR(VLOOKUP($A:$A,MASTER!$A:$T,19,0),0) -> 3123 | S11: =IFERROR(VLOOKUP($A:$A,MASTER!$A:$T,20,0),0) -> 2941 | T11: =IFERROR(R11/S11-1,0) -> 0.061883713 | U11: =IFERROR(VLOOKUP(A:A,MASTER!A:K,11,0),0) -> 9 | V11: =IFERROR(VLOOKUP(A:A,MASTER!A:L,12,0),0) -> 12 | W11: =IFERROR(U11/V11-1,0) -> -0.25
A12: MONTERADO|BENGKAYANG | B12: SDP MONTERADO | C12: =IFERROR(VLOOKUP($A:$A,MASTER!$A:$T,3,0),0) -> 3.5640456e+08 | D12: =IFERROR(VLOOKUP($A:$A,MASTER!$A:$T,4,0),0) -> 3.3345973e+08 | E12: =IFERROR(C12/D12-1,0) -> 0.068808414 | F12: =IFERROR(VLOOKUP(A:A,MASTER!A:E,5,0),0) -> 6194144.1 | G12: =IFERROR(VLOOKUP(A:A,MASTER!A:F,6,0),0) -> 5340540.5 | H12: =IFERROR(F12/G12-1,0) -> 0.15983468 | I12: =IFERROR(VLOOKUP(A:A,MASTER!A:M,13,0),0) -> 1.6979054e+08 | J12: =IFERROR(VLOOKUP($A:$A,MASTER!$A:$T,14,0),0) -> 1.5427928e+08 | K12: =IFERROR(I12/J12-1,0) -> 0.10054015 | L12: =IFERROR(VLOOKUP($A:$A,MASTER!$A:$T,15,0),0) -> 2.3364036e+08 | M12: =IFERROR(VLOOKUP($A:$A,MASTER!$A:$T,16,0),0) -> 2.3013688e+08 | N12: =IFERROR(L12/M12-1,0) -> 0.015223451 | O12: =IFERROR(VLOOKUP($A:$A,MASTER!$A:$T,17,0),0) -> 1.3943144e+08 | P12: =IFERROR(VLOOKUP($A:$A,MASTER!$A:$T,18,0),0) -> 1.345127e+08 | Q12: =IFERROR(O12/P12-1,0) -> 0.036567095 | R12: =IFERROR(VLOOKUP($A:$A,MASTER!$A:$T,19,0),0) -> 13158 | S12: =IFERROR(VLOOKUP($A:$A,MASTER!$A:$T,20,0),0) -> 12783 | T12: =IFERROR(R12/S12-1,0) -> 0.029335837 | U12: =IFERROR(VLOOKUP(A:A,MASTER!A:K,11,0),0) -> 504 | V12: =IFERROR(VLOOKUP(A:A,MASTER!A:L,12,0),0) -> 578 | W12: =IFERROR(U12/V12-1,0) -> -0.12802768
A13: SAMALANTAN|BENGKAYANG | B13: SDP MONTERADO | C13: =IFERROR(VLOOKUP($A:$A,MASTER!$A:$T,3,0),0) -> 77526033 | D13: =IFERROR(VLOOKUP($A:$A,MASTER!$A:$T,4,0),0) -> 80897189 | E13: =IFERROR(C13/D13-1,0) -> -0.041672099 | F13: =IFERROR(VLOOKUP(A:A,MASTER!A:E,5,0),0) -> 39189.189 | G13: =IFERROR(VLOOKUP(A:A,MASTER!A:F,6,0),0) -> 210810.81 | H13: =IFERROR(F13/G13-1,0) -> -0.81410256 | I13: =IFERROR(VLOOKUP(A:A,MASTER!A:M,13,0),0) -> 20006757 | J13: =IFERROR(VLOOKUP($A:$A,MASTER!$A:$T,14,0),0) -> 16372973 | K13: =IFERROR(I13/J13-1,0) -> 0.22193793 | L13: =IFERROR(VLOOKUP($A:$A,MASTER!$A:$T,15,0),0) -> 52325766 | M13: =IFERROR(VLOOKUP($A:$A,MASTER!$A:$T,16,0),0) -> 56972739 | N13: =IFERROR(L13/M13-1,0) -> -0.081564851 | O13: =IFERROR(VLOOKUP($A:$A,MASTER!$A:$T,17,0),0) -> 18856577 | P13: =IFERROR(VLOOKUP($A:$A,MASTER!$A:$T,18,0),0) -> 19149459 | Q13: =IFERROR(O13/P13-1,0) -> -0.015294577 | R13: =IFERROR(VLOOKUP($A:$A,MASTER!$A:$T,19,0),0) -> 4692 | S13: =IFERROR(VLOOKUP($A:$A,MASTER!$A:$T,20,0),0) -> 4794 | T13: =IFERROR(R13/S13-1,0) -> -0.021276596 | U13: =IFERROR(VLOOKUP(A:A,MASTER!A:K,11,0),0) -> 26 | V13: =IFERROR(VLOOKUP(A:A,MASTER!A:L,12,0),0) -> 34 | W13: =IFERROR(U13/V13-1,0) -> -0.23529412
A14: SANGGAU LEDO|BENGKAYANG | B14: SDP JAGOI BABANG | C14: =IFERROR(VLOOKUP($A:$A,MASTER!$A:$T,3,0),0) -> 1.1444757e+08 | D14: =IFERROR(VLOOKUP($A:$A,MASTER!$A:$T,4,0),0) -> 1.1059542e+08 | E14: =IFERROR(C14/D14-1,0) -> 0.034830984 | F14: =IFERROR(VLOOKUP(A:A,MASTER!A:E,5,0),0) -> 1381982 | G14: =IFERROR(VLOOKUP(A:A,MASTER!A:F,6,0),0) -> 1498198.2 | H14: =IFERROR(F14/G14-1,0) -> -0.077570655 | I14: =IFERROR(VLOOKUP(A:A,MASTER!A:M,13,0),0) -> 18324324 | J14: =IFERROR(VLOOKUP($A:$A,MASTER!$A:$T,14,0),0) -> 13322523 | K14: =IFERROR(I14/J14-1,0) -> 0.37543955 | L14: =IFERROR(VLOOKUP($A:$A,MASTER!$A:$T,15,0),0) -> 32753919 | M14: =IFERROR(VLOOKUP($A:$A,MASTER!$A:$T,16,0),0) -> 32151207 | N14: =IFERROR(L14/M14-1,0) -> 0.018746161 | O14: =IFERROR(VLOOKUP($A:$A,MASTER!$A:$T,17,0),0) -> 16726126 | P14: =IFERROR(VLOOKUP($A:$A,MASTER!$A:$T,18,0),0) -> 12859910 | Q14: =IFERROR(O14/P14-1,0) -> 0.300641 | R14: =IFERROR(VLOOKUP($A:$A,MASTER!$A:$T,19,0),0) -> 3755 | S14: =IFERROR(VLOOKUP($A:$A,MASTER!$A:$T,20,0),0) -> 4562 | T14: =IFERROR(R14/S14-1,0) -> -0.1768961 | U14: =IFERROR(VLOOKUP(A:A,MASTER!A:K,11,0),0) -> 12 | V14: =IFERROR(VLOOKUP(A:A,MASTER!A:L,12,0),0) -> 4 | W14: =IFERROR(U14/V14-1,0) -> 2
A15: SELUAS|BENGKAYANG | B15: SDP JAGOI BABANG | C15: =IFERROR(VLOOKUP($A:$A,MASTER!$A:$T,3,0),0) -> 2.2881864e+08 | D15: =IFERROR(VLOOKUP($A:$A,MASTER!$A:$T,4,0),0) -> 2.1841645e+08 | E15: =IFERROR(C15/D15-1,0) -> 0.047625485 | F15: =IFERROR(VLOOKUP(A:A,MASTER!A:E,5,0),0) -> 1239099.1 | G15: =IFERROR(VLOOKUP(A:A,MASTER!A:F,6,0),0) -> 1790991 | H15: =IFERROR(F15/G15-1,0) -> -0.30814889 | I15: =IFERROR(VLOOKUP(A:A,MASTER!A:M,13,0),0) -> 4.0698865e+08 | J15: =IFERROR(VLOOKUP($A:$A,MASTER!$A:$T,14,0),0) -> 2.459009e+08 | K15: =IFERROR(I15/J15-1,0) -> 0.65509214 | L15: =IFERROR(VLOOKUP($A:$A,MASTER!$A:$T,15,0),0) -> 80866568 | M15: =IFERROR(VLOOKUP($A:$A,MASTER!$A:$T,16,0),0) -> 80221847 | N15: =IFERROR(L15/M15-1,0) -> 0.0080367225 | O15: =IFERROR(VLOOKUP($A:$A,MASTER!$A:$T,17,0),0) -> 3.2062739e+08 | P15: =IFERROR(VLOOKUP($A:$A,MASTER!$A:$T,18,0),0) -> 2.3159694e+08 | Q15: =IFERROR(O15/P15-1,0) -> 0.38441981 | R15: =IFERROR(VLOOKUP($A:$A,MASTER!$A:$T,19,0),0) -> 7523 | S15: =IFERROR(VLOOKUP($A:$A,MASTER!$A:$T,20,0),0) -> 6133 | T15: =IFERROR(R15/S15-1,0) -> 0.22664275 | U15: =IFERROR(VLOOKUP(A:A,MASTER!A:K,11,0),0) -> 47 | V15: =IFERROR(VLOOKUP(A:A,MASTER!A:L,12,0),0) -> 36 | W15: =IFERROR(U15/V15-1,0) -> 0.30555556
A16: SIDING|BENGKAYANG | B16: SDP JAGOI BABANG | C16: =IFERROR(VLOOKUP($A:$A,MASTER!$A:$T,3,0),0) -> 0 | D16: =IFERROR(VLOOKUP($A:$A,MASTER!$A:$T,4,0),0) -> 0 | E16: =IFERROR(C16/D16-1,0) -> 0 | F16: =IFERROR(VLOOKUP(A:A,MASTER!A:E,5,0),0) -> 0 | G16: =IFERROR(VLOOKUP(A:A,MASTER!A:F,6,0),0) -> 0 | H16: =IFERROR(F16/G16-1,0) -> 0 | I16: =IFERROR(VLOOKUP(A:A,MASTER!A:M,13,0),0) -> 0 | J16: =IFERROR(VLOOKUP($A:$A,MASTER!$A:$T,14,0),0) -> 0 | K16: =IFERROR(I16/J16-1,0) -> 0 | L16: =IFERROR(VLOOKUP($A:$A,MASTER!$A:$T,15,0),0) -> 0 | M16: =IFERROR(VLOOKUP($A:$A,MASTER!$A:$T,16,0),0) -> 0 | N16: =IFERROR(L16/M16-1,0) -> 0 | O16: =IFERROR(VLOOKUP($A:$A,MASTER!$A:$T,17,0),0) -> 0 | P16: =IFERROR(VLOOKUP($A:$A,MASTER!$A:$T,18,0),0) -> 0 | Q16: =IFERROR(O16/P16-1,0) -> 0 | R16: =IFERROR(VLOOKUP($A:$A,MASTER!$A:$T,19,0),0) -> 0 | S16: =IFERROR(VLOOKUP($A:$A,MASTER!$A:$T,20,0),0) -> 0 | T16: =IFERROR(R16/S16-1,0) -> 0 | U16: =IFERROR(VLOOKUP(A:A,MASTER!A:K,11,0),0) -> 0 | V16: =IFERROR(VLOOKUP(A:A,MASTER!A:L,12,0),0) -> 0 | W16: =IFERROR(U16/V16-1,0) -> 0
A17: SUNGAI BETUNG|BENGKAYANG | B17: SDP MONTERADO | C17: =IFERROR(VLOOKUP($A:$A,MASTER!$A:$T,3,0),0) -> 95725205 | D17: =IFERROR(VLOOKUP($A:$A,MASTER!$A:$T,4,0),0) -> 89978474 | E17: =IFERROR(C17/D17-1,0) -> 0.063867841 | F17: =IFERROR(VLOOKUP(A:A,MASTER!A:E,5,0),0) -> 16666667 | G17: =IFERROR(VLOOKUP(A:A,MASTER!A:F,6,0),0) -> 18108108 | H17: =IFERROR(F17/G17-1,0) -> -0.07960199 | I17: =IFERROR(VLOOKUP(A:A,MASTER!A:M,13,0),0) -> 420045.05 | J17: =IFERROR(VLOOKUP($A:$A,MASTER!$A:$T,14,0),0) -> 440540.54 | K17: =IFERROR(I17/J17-1,0) -> -0.046523517 | L17: =IFERROR(VLOOKUP($A:$A,MASTER!$A:$T,15,0),0) -> 55199865 | M17: =IFERROR(VLOOKUP($A:$A,MASTER!$A:$T,16,0),0) -> 53496512 | N17: =IFERROR(L17/M17-1,0) -> 0.031840453 | O17: =IFERROR(VLOOKUP($A:$A,MASTER!$A:$T,17,0),0) -> 0 | P17: =IFERROR(VLOOKUP($A:$A,MASTER!$A:$T,18,0),0) -> 19639.64 | Q17: =IFERROR(O17/P17-1,0) -> -1 | R17: =IFERROR(VLOOKUP($A:$A,MASTER!$A:$T,19,0),0) -> 3867 | S17: =IFERROR(VLOOKUP($A:$A,MASTER!$A:$T,20,0),0) -> 3562 | T17: =IFERROR(R17/S17-1,0) -> 0.085626053 | U17: =IFERROR(VLOOKUP(A:A,MASTER!A:K,11,0),0) -> 8 | V17: =IFERROR(VLOOKUP(A:A,MASTER!A:L,12,0),0) -> 14 | W17: =IFERROR(U17/V17-1,0) -> -0.42857143
... A22: TUJUH BELAS|BENGKAYANG | B22: SDP JAGOI BABANG | C22: =IFERROR(VLOOKUP($A:$A,MASTER!$A:$T,3,0),0) -> 1.019717e+08 | D22: =IFERROR(VLOOKUP($A:$A,MASTER!$A:$T,4,0),0) -> 92309852 | E22: =IFERROR(C22/D22-1,0) -> 0.10466751 | F22: =IFERROR(VLOOKUP(A:A,MASTER!A:E,5,0),0) -> 80180.18 | G22: =IFERROR(VLOOKUP(A:A,MASTER!A:F,6,0),0) -> 713513.51 | H22: =IFERROR(F22/G22-1,0) -> -0.88762626 | I22: =IFERROR(VLOOKUP(A:A,MASTER!A:M,13,0),0) -> 9575495.5 | J22: =IFERROR(VLOOKUP($A:$A,MASTER!$A:$T,14,0),0) -> 26611712 | K22: =IFERROR(I22/J22-1,0) -> -0.64017739 | L22: =IFERROR(VLOOKUP($A:$A,MASTER!$A:$T,15,0),0) -> 33544676 | M22: =IFERROR(VLOOKUP($A:$A,MASTER!$A:$T,16,0),0) -> 31675387 | N22: =IFERROR(L22/M22-1,0) -> 0.059013905 | O22: =IFERROR(VLOOKUP($A:$A,MASTER!$A:$T,17,0),0) -> 10369459 | P22: =IFERROR(VLOOKUP($A:$A,MASTER!$A:$T,18,0),0) -> 29439099 | Q22: =IFERROR(O22/P22-1,0) -> -0.64776573 | R22: =IFERROR(VLOOKUP($A:$A,MASTER!$A:$T,19,0),0) -> 3797 | S22: =IFERROR(VLOOKUP($A:$A,MASTER!$A:$T,20,0),0) -> 3106 | T22: =IFERROR(R22/S22-1,0) -> 0.22247263 | U22: =IFERROR(VLOOKUP(A:A,MASTER!A:K,11,0),0) -> 10 | V22: =IFERROR(VLOOKUP(A:A,MASTER!A:L,12,0),0) -> 19 | W22: =IFERROR(U22/V22-1,0) -> -0.47368421

Sheet MASTER
A2: parameter | C2: Prepaid Rev | D2: Prepaid Rev | E2: Primary | F2: Primary | G2: QSC 100MB | H2: QSC 100MB | I2: RGUGA FWA ALL CHANNEL | J2: RGUGA FWA ALL CHANNEL | K2: RGUGA-Trad | L2: RGUGA-Trad | M2: Secondary | N2: Secondary | O2: Tertiary B# | P2: Tertiary B# | Q2: Trade Supply | R2: Trade Supply | S2: VLR_SUBS | T2: VLR_SUBS
A3: kec_unik | B3: pt_id | C3: MTD | D3: LMTD | E3: MTD | F3: LMTD | G3: MTD | H3: LMTD | I3: MTD | J3: LMTD | K3: MTD | L3: LMTD | M3: MTD | N3: LMTD | O3: MTD | P3: LMTD | Q3: MTD | R3: LMTD | S3: MTD | T3: LMTD
A4: AIR UPAS|KETAPANG | B4: PT-PEMAHAN | C4: 2.7245904e+08 | D4: 2.9219129e+08 | E4: 75731386 | F4: 87773542 | G4: 14 | H4: 33 | K4: 15 | L4: 44 | M4: 17165586 | N4: 28350631 | O4: 32053018 | P4: 37055865 | Q4: 10545676 | R4: 20635135 | S4: 7466 | T4: 8300
A5: ALALAK|BARITO KUALA | B5: PT-MEKAR SARI | C5: 4.7153999e+08 | D5: 4.47142e+08 | E5: 2847027 | F5: 3945945.9 | G5: 94 | H5: 291 | I5: 8 | K5: 112 | L5: 476 | M5: 1.1046622e+08 | N5: 82717928 | O5: 1.3927721e+08 | P5: 1.4135233e+08 | Q5: 1.0516622e+08 | R5: 79771532 | S5: 21277 | T5: 19616
A6: ALUH-ALUH|BANJAR | B6: PT-MARTAPURA | C6: 1.1073432e+08 | D6: 1.1238662e+08 | E6: 61261.261 | F6: 2621621.6 | G6: 19 | H6: 43 | K6: 19 | L6: 52 | M6: 17159009 | N6: 28903153 | O6: 37959937 | P6: 35768892 | Q6: 7300000 | R6: 21724685 | S6: 5132 | T6: 4611
A7: AMUNTAI SELATAN|HULU SUNGAI UTARA | B7: PT-TANJUNG | C7: 60546273 | D7: 59966807 | E7: 649099.1 | F7: 451351.35 | G7: 10 | H7: 16 | K7: 14 | L7: 19 | M7: 7708108.1 | N7: 5530991 | O7: 20104874 | P7: 19014795 | Q7: 7459009 | R7: 5865315.3 | S7: 3867 | T7: 2920
A8: AMUNTAI TENGAH|HULU SUNGAI UTARA | B8: PT-TANJUNG | C8: 1.0183004e+08 | D8: 99074865 | E8: 402252.25 | F8: 1970270.3 | G8: 29 | H8: 30 | K8: 47 | L8: 87 | M8: 26962613 | N8: 18670090 | O8: 25127054 | P8: 28465847 | Q8: 22413784 | R8: 35404865 | S8: 4544 | T8: 5039
A9: AMUNTAI UTARA|HULU SUNGAI UTARA | B9: PT-TANJUNG | C9: 51520091 | D9: 47988786 | E9: 548828.83 | F9: 652252.25 | G9: 5 | H9: 11 | K9: 8 | L9: 12 | M9: 4486666.7 | N9: 5538738.7 | O9: 15561351 | P9: 14565477 | Q9: 3845315.3 | R9: 4532432.4 | S9: 2095 | T9: 2051
A10: ANGGANA|KUTAI KARTANEGARA | B10: PT-TENGGARONG | C10: 1.3147223e+08 | D10: 1.3215061e+08 | E10: 905405.41 | F10: 121621.62 | G10: 37 | H10: 39 | K10: 46 | L10: 44 | M10: 3626126.1 | N10: 3364864.9 | O10: 23009414 | P10: 24730387 | Q10: 2607837.8 | R10: 2124504.5 | S10: 5649 | T10: 5395
A11: ANGKINANG|HULU SUNGAI SELATAN | B11: PT-KANDANGAN | C11: 56411947 | D11: 55910661 | E11: 199639.64 | F11: 423423.42 | G11: 10 | H11: 20 | K11: 10 | L11: 31 | M11: 5641081.1 | N11: 7486486.5 | O11: 26727964 | P11: 25562658 | Q11: 5193333.3 | R11: 6654594.6 | S11: 2932 | T11: 2983
A12: ANGSANA|TANAH BUMBU | B12: PT-BATULICIN | C12: 2.691711e+08 | D12: 2.5624792e+08 | E12: 57657.658 | F12: 2955405.4 | G12: 56 | H12: 30 | K12: 75 | L12: 35 | M12: 4732792.8 | N12: 47861441 | O12: 27708108 | P12: 26394550 | Q12: 5435405.4 | R12: 44792342 | S12: 8766 | T12: 8765
A13: ANJIR MUARA|BARITO KUALA | B13: PT-MEKAR SARI | C13: 1.410468e+08 | D13: 1.3682508e+08 | E13: 649549.55 | F13: 1553153.2 | G13: 23 | H13: 55 | K13: 25 | L13: 80 | M13: 52203964 | N13: 24123784 | O13: 52009532 | P13: 50581297 | Q13: 51675135 | R13: 25756937 | S13: 3740 | T13: 5738
A14: ANJIR PASAR|BARITO KUALA | B14: PT-MEKAR SARI | C14: 1.4490605e+08 | D14: 1.3952176e+08 | E14: 1277027 | F14: 2169369.4 | G14: 17 | H14: 37 | K14: 22 | L14: 48 | M14: 24660450 | N14: 14965045 | O14: 54183856 | P14: 51662865 | Q14: 23907117 | R14: 13845586 | S14: 4255 | T14: 5571
A15: ANJONGAN|MEMPAWAH | B15: PT-MEMPAWAH | C15: 1.4483163e+08 | D15: 1.404759e+08 | E15: 1464054.1 | F15: 3115315.3 | G15: 58 | H15: 37 | K15: 65 | L15: 60 | M15: 33800721 | N15: 1.2689883e+08 | O15: 71782243 | P15: 72445207 | Q15: 23680360 | R15: 58436577 | S15: 5866 | T15: 5427
A16: ANTANG KALANG|KOTAWARINGIN TIMUR | B16: PT-ANTANG KALANG | C16: 83885801 | D16: 82195091 | E16: 4815765.8 | F16: 14998198 | G16: 40 | H16: 23 | K16: 48 | L16: 27 | M16: 14985495 | N16: 16263514 | O16: 22015631 | P16: 22377360 | Q16: 10748829 | R16: 10884775 | S16: 3521 | T16: 3117
A17: ARANIO|BANJAR | B17: PT-KARANG INTAN | C17: 6518856.3 | D17: 6429962 | F17: 13513.514 | G17: 1 | H17: 1 | K17: 1 | L17: 1 | M17: 275675.68 | N17: 193693.69 | O17: 1439054.1 | P17: 2063153.2 | Q17: 254054.05 | R17: 158558.56 | S17: 581 | T17: 278
A18: ARUT SELATAN|KOTAWARINGIN BARAT | B18: PT-PANGKALANBUN | C18: 1.1811015e+09 | D18: 1.1310667e+09 | E18: 3.2709385e+08 | F18: 3.0778892e+08 | G18: 299 | H18: 277 | I18: 15 | K18: 486 | L18: 498 | M18: 1.3972591e+08 | N18: 1.2461172e+08 | O18: 2.225881e+08 | P18: 2.2748013e+08 | Q18: 1.1639279e+08 | R18: 1.0611058e+08 | S18: 46886 | T18: 45716
A19: ARUT UTARA|KOTAWARINGIN BARAT | B19: PT-PANGKALANBUN | C19: 1.1370567e+08 | D19: 1.1545151e+08 | E19: 3603.6036 | F19: 72972.973 | G19: 28 | H19: 33 | K19: 35 | L19: 35 | M19: 2553153.2 | N19: 2460360.4 | O19: 15571712 | P19: 16435360 | Q19: 1796846.8 | R19: 2521891.9 | S19: 3723 | T19: 3433
A20: ASTAMBUL|BANJAR | B20: PT-KARANG INTAN | C20: 1.1569814e+08 | D20: 1.1205456e+08 | E20: 483423.42 | F20: 3482882.9 | G20: 30 | H20: 36 | K20: 35 | L20: 55 | M20: 21473964 | N20: 25227928 | O20: 38841018 | P20: 40642568 | Q20: 33562252 | R20: 22709189 | S20: 4142 | T20: 4114
A21: AWANG|BARITO TIMUR | B21: PT-SOUTH BARITO | C21: 32494225 | D21: 32635387 | E21: 77477.477 | F21: 77477.477 | G21: 9 | H21: 5 | K21: 10 | L21: 5 | M21: 4108108.1 | N21: 3284864.9 | O21: 8002252.3 | P21: 8334567.6 | Q21: 2980900.9 | R21: 2572522.5 | S21: 1465 | T21: 1436
A22: AWAYAN|BALANGAN | B22: PT-BARABAI | C22: 75314671 | D22: 69189585 | E22: 460450.45 | F22: 881081.08 | G22: 20 | H22: 13 | K22: 21 | L22: 16 | M22: 10037027 | N22: 6962162.2 | O22: 24030901 | P22: 22398279 | Q22: 7923423.4 | R22: 9288378.4 | S22: 3122 | T22: 2462
A23: BAAMANG|KOTAWARINGIN TIMUR | B23: PT-SAMPIT | C23: 6.9371163e+08 | D23: 6.6194639e+08 | E23: 2150900.9 | F23: 3300000 | G23: 216 | H23: 417 | I23: 3 | K23: 274 | L23: 511 | M23: 2.0333721e+08 | N23: 68203604 | O23: 1.6902505e+08 | P23: 1.7044328e+08 | Q23: 58872162 | R23: 57167027 | S23: 26560 | T23: 26398
A24: BABIRIK|HULU SUNGAI UTARA | B24: PT-TANJUNG | C24: 19548627 | D24: 19733580 | E24: 141441.44 | F24: 125225.23 | G24: 7 | H24: 7 | K24: 9 | L24: 8 | M24: 2213964 | N24: 958558.56 | O24: 4250900.9 | P24: 4431036 | Q24: 2199549.5 | R24: 1110720.7 | S24: 1128 | T24: 1454
A25: BABULU|PENAJAM PASER UTARA | B25: PT-PENAJAM | C25: 4.8104074e+08 | D25: 4.70543e+08 | E25: 2927117.1 | F25: 4441666.7 | G25: 77 | H25: 85 | I25: 1 | K25: 92 | L25: 97 | M25: 86865856 | N25: 1.0770586e+08 | O25: 1.3044369e+08 | P25: 1.351349e+08 | Q25: 75558108 | R25: 66709459 | S25: 15052 | T25: 15486
A26: BADAU|KAPUAS HULU | B26: PT-BADAU KAPUAS | C26: 49728471 | D26: 43130759 | E26: 136936.94 | F26: 993468.47 | G26: 17 | H26: 28 | K26: 24 | L26: 34 | M26: 46418468 | N26: 69661622 | O26: 16959414 | P26: 16440640 | Q26: 34920090 | R26: 61225766 | S26: 2299 | T26: 2090
A27: BAHAU HULU|MALINAU | B27: PT-MALINAU BARAT | C27: 1960981.1 | D27: 1703110.3 | G27: 2 | H27: 1 | K27: 2 | L27: 1 | M27: 108108.11 | N27: 567567.57 | O27: 628423.42 | P27: 778837.84 | S27: 158 | T27: 165
A28: BAJUIN|TANAH LAUT | B28: PT-PELAIHARI | C28: 97519099 | D28: 96306800 | E28: 45045.045 | F28: 892792.79 | G28: 10 | H28: 12 | K28: 13 | L28: 13 | M28: 8907747.7 | N28: 14812793 | O28: 34039189 | P28: 33288261 | Q28: 7552162.2 | R28: 15190541 | S28: 3440 | T28: 3189
A29: BAKARANGAN|TAPIN | B29: PT-KANDANGAN | C29: 32540972 | D29: 35411955 | E29: 54954.955 | F29: 73873.874 | G29: 11 | H29: 6 | K29: 51 | L29: 81 | M29: 3208108.1 | N29: 2614414.4 | O29: 18412883 | P29: 20918811 | Q29: 2690991 | R29: 2721261.3 | S29: 1503 | T29: 1580
A30: BAKUMPAI|BARITO KUALA | B30: PT-MARABAHAN | C30: 28695435 | D30: 29018728 | F30: 1954054.1 | G30: 9 | H30: 6 | K30: 10 | L30: 9 | M30: 60540.541 | N30: 11107207 | O30: 9444729.7 | P30: 8950216.2 | Q30: 60540.541 | R30: 10565946 | S30: 1025 | T30: 1091
A31: BALAI RIAM|SUKAMARA | B31: PT-LAMANDAU | C31: 1.3069635e+08 | D31: 1.2357103e+08 | E31: 33333.333 | F31: 184684.68 | G31: 32 | H31: 19 | K31: 37 | L31: 21 | M31: 12972973 | N31: 13927928 | O31: 17638559 | P31: 17492458 | Q31: 12836396 | R31: 12295856 | S31: 4400 | T31: 4484
A32: BALAI|SANGGAU | B32: PT-TAYAN HILIR | C32: 1.3027105e+08 | D32: 1.2824918e+08 | E32: 15965766 | F32: 74051351 | G32: 31 | H32: 25 | K32: 36 | L32: 29 | M32: 21000045 | N32: 35838063 | O32: 60098144 | P32: 63351477 | Q32: 16941892 | R32: 19939730 | S32: 6161 | T32: 5873
A33: BALIKPAPAN BARAT|KOTA BALIKPAPAN | B33: PT-BALIKPAPAN | C33: 4.6513808e+08 | D33: 4.6103995e+08 | E33: 1612702.7 | F33: 3562162.2 | G33: 208 | H33: 177 | K33: 236 | L33: 213 | M33: 62773423 | N33: 1.0260676e+08 | O33: 1.1914271e+08 | P33: 1.1898417e+08 | Q33: 57592703 | R33: 54357387 | S33: 21540 | T33: 22085
A34: BALIKPAPAN KOTA|KOTA BALIKPAPAN | B34: PT-BALIKPAPAN | C34: 7.7426657e+08 | D34: 7.4809772e+08 | E34: 43185029 | F34: 3297949.5 | G34: 215 | H34: 201 | K34: 270 | L34: 350 | M34: 66683874 | N34: 50047748 | O34: 1.470293e+08 | P34: 1.4514027e+08 | Q34: 54019775 | R34: 41142793 | S34: 29355 | T34: 29446
A35: BALIKPAPAN SELATAN|KOTA BALIKPAPAN | B35: PT-BALIKPAPAN | C35: 7.4109026e+08 | D35: 7.9183551e+08 | E35: 1729729.7 | F35: 7523423.4 | G35: 147 | H35: 174 | I35: 5 | K35: 278 | L35: 411 | M35: 5.2571122e+08 | N35: 2.5020428e+08 | O35: 1.4724521e+08 | P35: 3.7931269e+08 | Q35: 5.2257108e+08 | R35: 64944910 | S35: 33170 | T35: 32811
A36: BALIKPAPAN TENGAH|KOTA BALIKPAPAN | B36: PT-BALIKPAPAN | C36: 4.4197332e+08 | D36: 4.3111943e+08 | E36: 502702.7 | F36: 2159459.5 | G36: 143 | H36: 115 | I36: 1 | K36: 175 | L36: 153 | M36: 30145405 | N36: 29205405 | O36: 94591476 | P36: 95767297 | Q36: 31996847 | R36: 30921171 | S36: 21281 | T36: 21331
A37: BALIKPAPAN TIMUR|KOTA BALIKPAPAN | B37: PT-BALIKPAPAN | C37: 4.8797288e+08 | D37: 4.8787845e+08 | E37: 1886982 | F37: 4481081.1 | G37: 88 | H37: 108 | I37: 1 | K37: 100 | L37: 150 | M37: 74316306 | N37: 49285586 | O37: 1.3717801e+08 | P37: 1.4205391e+08 | Q37: 63861261 | R37: 70712162 | S37: 25255 | T37: 25185
A38: BALIKPAPAN UTARA|KOTA BALIKPAPAN | B38: PT-BALIKPAPAN | C38: 1.2602542e+09 | D38: 1.2509678e+09 | E38: 4.4799084e+08 | F38: 1.9324133e+08 | G38: 354 | H38: 307 | I38: 14 | K38: 456 | L38: 455 | M38: 1.2174162e+08 | N38: 1.1605856e+08 | O38: 2.5558389e+08 | P38: 2.6705215e+08 | Q38: 1.1595572e+08 | R38: 1.1681243e+08 | S38: 54976 | T38: 54785
A39: BANAMA TINGANG|PULANG PISAU | B39: PT-PULANG PISAU | C39: 98834080 | D39: 87902777 | E39: 190090.09 | F39: 458558.56 | G39: 22 | H39: 16 | K39: 27 | L39: 17 | M39: 1032432.4 | N39: 909009.01 | O39: 17798378 | P39: 18125613 | Q39: 899909.91 | R39: 570720.72 | S39: 2752 | T39: 2504
A40: BANJANG|HULU SUNGAI UTARA | B40: PT-TANJUNG | C40: 30506664 | D40: 28360680 | E40: 139639.64 | F40: 21621.622 | G40: 12 | H40: 14 | K40: 26 | L40: 27 | M40: 1108558.6 | N40: 594234.23 | O40: 7166801.8 | P40: 7810621.6 | Q40: 1426036 | R40: 1073603.6 | S40: 1448 | T40: 1369
A41: BANJARBARU SELATAN|KOTA BANJARBARU | B41: PT-BANJARBARU | C41: 2.5078333e+08 | D41: 2.3875792e+08 | E41: 590270.27 | F41: 2794594.6 | G41: 68 | H41: 66 | K41: 87 | L41: 83 | M41: 26773153 | N41: 30661081 | O41: 52443870 | P41: 54363820 | Q41: 20879099 | R41: 26858468 | S41: 10583 | T41: 9919
...
