Workbook

Sheet Sheet1
A5: KECAMATAN | B5: PARTNER | C5: REVENUE MTD | D5: REVENUE LMTD | E5: GROWTH | F5: PRIMARY MTD | G5: PRIMARY LMTD | H5: GROWTH | I5: SECONDARY MTD | J5: SECONDARY LMTD | K5: GROWTH | L5: TERTIARY B# MTD | M5: TERTIARY B# LMTD | N5: GROWTH | O5: TRADE SUPPLY MTD | P5: TRADE SUPPLY LMTD | Q5: GROWTH | R5: VLR SUBS MTD | S5: VLR SUBS LMTD | T5: GROWTH | U5: RGUGA TRADE MTD | V5: RGUGA TRADE LMTD | W5: GROWTH | X5: SP SELL IN MTD | Y5: SP SELL IN LMTD | Z5: GROWTH
A6: BENGKAYANG|BENGKAYANG | B6: SDP JAGOI BABANG | C6: =IFERROR(VLOOKUP(A:A,MASTER!A:C,3,0),0) -> 5.4068004e+08 | D6: =IFERROR(VLOOKUP(A:A,MASTER!A:D,4,0),0) -> 5.5118409e+08 | E6: =IFERROR(C6/D6-1,0) -> -0.019057235 | F6: =IFERROR(VLOOKUP(A6,MASTER!A:E,5,0),0) -> 2345045 | G6: =IFERROR(VLOOKUP(A6,MASTER!A:F,6,0),0) -> 554504.5 | H6: =IFERROR(F6/G6-1,0) -> 3.229082 | I6: =IFERROR(VLOOKUP(A6,MASTER!A:O,15,0),0) -> 29442523 | J6: =IFERROR(VLOOKUP(A6,MASTER!A:P,16,0),0) -> 52789279 | K6: =IFERROR(I6/J6-1,0) -> -0.44226322 | L6: =IFERROR(VLOOKUP(A6,MASTER!A:S,19,0),0) -> 2.2902926e+08 | M6: =IFERROR(VLOOKUP(A6,MASTER!A:T,20,0),0) -> 2.3244551e+08 | N6: =IFERROR(L6/M6-1,0) -> -0.014697014 | O6: =IFERROR(VLOOKUP(A6,MASTER!A:U,21,0),0) -> 35277748 | P6: =IFERROR(VLOOKUP(A6,MASTER!A:V,22,0),0) -> 54031982 | Q6: =IFERROR(O6/P6-1,0) -> -0.34709506 | R6: =IFERROR(VLOOKUP(A6,MASTER!A:W,23,0),0) -> 10893.192 | S6: =IFERROR(VLOOKUP(A6,MASTER!A:X,24,0),0) -> 10580.538 | T6: =IFERROR(R6/S6-1,0) -> 0.029549899 | U6: =IFERROR(VLOOKUP(A6,MASTER!A:M,13,0),0) -> 950 | V6: =IFERROR(VLOOKUP(A6,MASTER!A:N,14,0),0) -> 945 | W6: =IFERROR(U6/V6-1,0) -> 0.0052910053 | X6: =IFERROR(VLOOKUP(A6,MASTER!A:Q,17,0),0) -> 135 | Y6: =IFERROR(VLOOKUP(A6,MASTER!A:R,18,0),0) -> 256 | Z6: =IFERROR(X6/Y6-1,0) -> -0.47265625
A7: JAGOI BABANG|BENGKAYANG | B7: SDP JAGOI BABANG | C7: =IFERROR(VLOOKUP(A:A,MASTER!A:C,3,0),0) -> 3.390007e+08 | D7: =IFERROR(VLOOKUP(A:A,MASTER!A:D,4,0),0) -> 3.569072e+08 | E7: =IFERROR(C7/D7-1,0) -> -0.050171319 | F7: =IFERROR(VLOOKUP(A7,MASTER!A:E,5,0),0) -> 518018.02 | G7: =IFERROR(VLOOKUP(A7,MASTER!A:F,6,0),0) -> 3265540.5 | H7: =IFERROR(F7/G7-1,0) -> -0.84136837 | I7: =IFERROR(VLOOKUP(A7,MASTER!A:O,15,0),0) -> 64502252 | J7: =IFERROR(VLOOKUP(A7,MASTER!A:P,16,0),0) -> 66095946 | K7: =IFERROR(I7/J7-1,0) -> -0.024111822 | L7: =IFERROR(VLOOKUP(A7,MASTER!A:S,19,0),0) -> 87510180 | M7: =IFERROR(VLOOKUP(A7,MASTER!A:T,20,0),0) -> 90549437 | N7: =IFERROR(L7/M7-1,0) -> -0.033564612 | O7: =IFERROR(VLOOKUP(A7,MASTER!A:U,21,0),0) -> 64945946 | P7: =IFERROR(VLOOKUP(A7,MASTER!A:V,22,0),0) -> 63523153 | Q7: =IFERROR(O7/P7-1,0) -> 0.022398019 | R7: =IFERROR(VLOOKUP(A7,MASTER!A:W,23,0),0) -> 4028.8077 | S7: =IFERROR(VLOOKUP(A7,MASTER!A:X,24,0),0) -> 4073.4231 | T7: =IFERROR(R7/S7-1,0) -> -0.010952799 | U7: =IFERROR(VLOOKUP(A7,MASTER!A:M,13,0),0) -> 41 | V7: =IFERROR(VLOOKUP(A7,MASTER!A:N,14,0),0) -> 62 | W7: =IFERROR(U7/V7-1,0) -> -0.33870968 | X7: =IFERROR(VLOOKUP(A7,MASTER!A:Q,17,0),0) -> 161 | Y7: =IFERROR(VLOOKUP(A7,MASTER!A:R,18,0),0) -> 149 | Z7: =IFERROR(X7/Y7-1,0) -> 0.080536913
A8: LEDO|BENGKAYANG | B8: SDP JAGOI BABANG | C8: =IFERROR(VLOOKUP(A:A,MASTER!A:C,3,0),0) -> 2.5302774e+08 | D8: =IFERROR(VLOOKUP(A:A,MASTER!A:D,4,0),0) -> 2.6130756e+08 | E8: =IFERROR(C8/D8-1,0) -> -0.0316861 | F8: =IFERROR(VLOOKUP(A8,MASTER!A:E,5,0),0) -> 1182882.9 | G8: =IFERROR(VLOOKUP(A8,MASTER!A:F,6,0),0) -> 1290991 | H8: =IFERROR(F8/G8-1,0) -> -0.083740405 | I8: =IFERROR(VLOOKUP(A8,MASTER!A:O,15,0),0) -> 38605013 | J8: =IFERROR(VLOOKUP(A8,MASTER!A:P,16,0),0) -> 2.0286162e+08 | K8: =IFERROR(I8/J8-1,0) -> -0.8096978 | L8: =IFERROR(VLOOKUP(A8,MASTER!A:S,19,0),0) -> 88875941 | M8: =IFERROR(VLOOKUP(A8,MASTER!A:T,20,0),0) -> 92484523 | N8: =IFERROR(L8/M8-1,0) -> -0.039018216 | O8: =IFERROR(VLOOKUP(A8,MASTER!A:U,21,0),0) -> 52948919 | P8: =IFERROR(VLOOKUP(A8,MASTER!A:V,22,0),0) -> 1.6720477e+08 | Q8: =IFERROR(O8/P8-1,0) -> -0.68332891 | R8: =IFERROR(VLOOKUP(A8,MASTER!A:W,23,0),0) -> 4562.9231 | S8: =IFERROR(VLOOKUP(A8,MASTER!A:X,24,0),0) -> 4416.1538 | T8: =IFERROR(R8/S8-1,0) -> 0.033234628 | U8: =IFERROR(VLOOKUP(A8,MASTER!A:M,13,0),0) -> 18 | V8: =IFERROR(VLOOKUP(A8,MASTER!A:N,14,0),0) -> 21 | W8: =IFERROR(U8/V8-1,0) -> -0.14285714 | X8: =IFERROR(VLOOKUP(A8,MASTER!A:Q,17,0),0) -> 124 | Y8: =IFERROR(VLOOKUP(A8,MASTER!A:R,18,0),0) -> 150 | Z8: =IFERROR(X8/Y8-1,0) -> -0.17333333
A9: LUMAR|BENGKAYANG | B9: SDP JAGOI BABANG | C9: =IFERROR(VLOOKUP(A:A,MASTER!A:C,3,0),0) -> 2.1835647e+08 | D9: =IFERROR(VLOOKUP(A:A,MASTER!A:D,4,0),0) -> 2.1245902e+08 | E9: =IFERROR(C9/D9-1,0) -> 0.027758031 | F9: =IFERROR(VLOOKUP(A9,MASTER!A:E,5,0),0) -> 1265765.8 | G9: =IFERROR(VLOOKUP(A9,MASTER!A:F,6,0),0) -> 2278828.8 | H9: =IFERROR(F9/G9-1,0) -> -0.44455426 | I9: =IFERROR(VLOOKUP(A9,MASTER!A:O,15,0),0) -> 11107207 | J9: =IFERROR(VLOOKUP(A9,MASTER!A:P,16,0),0) -> 17379009 | K9: =IFERROR(I9/J9-1,0) -> -0.36088374 | L9: =IFERROR(VLOOKUP(A9,MASTER!A:S,19,0),0) -> 86031532 | M9: =IFERROR(VLOOKUP(A9,MASTER!A:T,20,0),0) -> 89409450 | N9: =IFERROR(L9/M9-1,0) -> -0.037780334 | O9: =IFERROR(VLOOKUP(A9,MASTER!A:U,21,0),0) -> 11145135 | P9: =IFERROR(VLOOKUP(A9,MASTER!A:V,22,0),0) -> 15803784 | Q9: =IFERROR(O9/P9-1,0) -> -0.29478059 | R9: =IFERROR(VLOOKUP(A9,MASTER!A:W,23,0),0) -> 3437 | S9: =IFERROR(VLOOKUP(A9,MASTER!A:X,24,0),0) -> 3259.3077 | T9: =IFERROR(R9/S9-1,0) -> 0.054518421 | U9: =IFERROR(VLOOKUP(A9,MASTER!A:M,13,0),0) -> 32 | V9: =IFERROR(VLOOKUP(A9,MASTER!A:N,14,0),0) -> 16 | W9: =IFERROR(U9/V9-1,0) -> 1 | X9: =IFERROR(VLOOKUP(A9,MASTER!A:Q,17,0),0) -> 35 | Y9: =IFERROR(VLOOKUP(A9,MASTER!A:R,18,0),0) -> 121 | Z9: =IFERROR(X9/Y9-1,0) -> -0.7107438
A10: SANGGAU LEDO|BENGKAYANG | B10: SDP JAGOI BABANG | C10: =IFERROR(VLOOKUP(A:A,MASTER!A:C,3,0),0) -> 2.8581384e+08 | D10: =IFERROR(VLOOKUP(A:A,MASTER!A:D,4,0),0) -> 2.8226916e+08 | E10: =IFERROR(C10/D10-1,0) -> 0.012557817 | F10: =IFERROR(VLOOKUP(A10,MASTER!A:E,5,0),0) -> 6577927.9 | G10: =IFERROR(VLOOKUP(A10,MASTER!A:F,6,0),0) -> 2347747.7 | H10: =IFERROR(F10/G10-1,0) -> 1.8018035 | I10: =IFERROR(VLOOKUP(A10,MASTER!A:O,15,0),0) -> 20001171 | J10: =IFERROR(VLOOKUP(A10,MASTER!A:P,16,0),0) -> 36330180 | K10: =IFERROR(I10/J10-1,0) -> -0.44946127 | L10: =IFERROR(VLOOKUP(A10,MASTER!A:S,19,0),0) -> 75785932 | M10: =IFERROR(VLOOKUP(A10,MASTER!A:T,20,0),0) -> 79501023 | N10: =IFERROR(L10/M10-1,0) -> -0.046730092 | O10: =IFERROR(VLOOKUP(A10,MASTER!A:U,21,0),0) -> 20815315 | P10: =IFERROR(VLOOKUP(A10,MASTER!A:V,22,0),0) -> 37203333 | Q10: =IFERROR(O10/P10-1,0) -> -0.44049865 | R10: =IFERROR(VLOOKUP(A10,MASTER!A:W,23,0),0) -> 4382.2692 | S10: =IFERROR(VLOOKUP(A10,MASTER!A:X,24,0),0) -> 4341.0769 | T10: =IFERROR(R10/S10-1,0) -> 0.0094889606 | U10: =IFERROR(VLOOKUP(A10,MASTER!A:M,13,0),0) -> 37 | V10: =IFERROR(VLOOKUP(A10,MASTER!A:N,14,0),0) -> 33 | W10: =IFERROR(U10/V10-1,0) -> 0.12121212 | X10: =IFERROR(VLOOKUP(A10,MASTER!A:Q,17,0),0) -> 72 | Y10: =IFERROR(VLOOKUP(A10,MASTER!A:R,18,0),0) -> 122 | Z10: =IFERROR(X10/Y10-1,0) -> -0.40983607
A11: SELUAS|BENGKAYANG | B11: SDP JAGOI BABANG | C11: =IFERROR(VLOOKUP(A:A,MASTER!A:C,3,0),0) -> 6.3238269e+08 | D11: =IFERROR(VLOOKUP(A:A,MASTER!A:D,4,0),0) -> 5.986278e+08 | E11: =IFERROR(C11/D11-1,0) -> 0.056387111 | F11: =IFERROR(VLOOKUP(A11,MASTER!A:E,5,0),0) -> 4.5190269e+08 | G11: =IFERROR(VLOOKUP(A11,MASTER!A:F,6,0),0) -> 8.2114761e+08 | H11: =IFERROR(F11/G11-1,0) -> -0.44966937 | I11: =IFERROR(VLOOKUP(A11,MASTER!A:O,15,0),0) -> 5.4798147e+08 | J11: =IFERROR(VLOOKUP(A11,MASTER!A:P,16,0),0) -> 7.5647376e+08 | K11: =IFERROR(I11/J11-1,0) -> -0.27561073 | L11: =IFERROR(VLOOKUP(A11,MASTER!A:S,19,0),0) -> 2.0678482e+08 | M11: =IFERROR(VLOOKUP(A11,MASTER!A:T,20,0),0) -> 2.0217071e+08 | N11: =IFERROR(L11/M11-1,0) -> 0.022822832 | O11: =IFERROR(VLOOKUP(A11,MASTER!A:U,21,0),0) -> 5.9180405e+08 | P11: =IFERROR(VLOOKUP(A11,MASTER!A:V,22,0),0) -> 6.1203676e+08 | Q11: =IFERROR(O11/P11-1,0) -> -0.033057986 | R11: =IFERROR(VLOOKUP(A11,MASTER!A:W,23,0),0) -> 9119.6154 | S11: =IFERROR(VLOOKUP(A11,MASTER!A:X,24,0),0) -> 8867.1154 | T11: =IFERROR(R11/S11-1,0) -> 0.028476003 | U11: =IFERROR(VLOOKUP(A11,MASTER!A:M,13,0),0) -> 233 | V11: =IFERROR(VLOOKUP(A11,MASTER!A:N,14,0),0) -> 153 | W11: =IFERROR(U11/V11-1,0) -> 0.52287582 | X11: =IFERROR(VLOOKUP(A11,MASTER!A:Q,17,0),0) -> 296 | Y11: =IFERROR(VLOOKUP(A11,MASTER!A:R,18,0),0) -> 685 | Z11: =IFERROR(X11/Y11-1,0) -> -0.56788321
A12: SIDING|BENGKAYANG | B12: SDP JAGOI BABANG | C12: =IFERROR(VLOOKUP(A:A,MASTER!A:C,3,0),0) -> 0 | D12: =IFERROR(VLOOKUP(A:A,MASTER!A:D,4,0),0) -> 0 | E12: =IFERROR(C12/D12-1,0) -> 0 | F12: =IFERROR(VLOOKUP(A12,MASTER!A:E,5,0),0) -> 0 | G12: =IFERROR(VLOOKUP(A12,MASTER!A:F,6,0),0) -> 0 | H12: =IFERROR(F12/G12-1,0) -> 0 | I12: =IFERROR(VLOOKUP(A12,MASTER!A:O,15,0),0) -> 0 | J12: =IFERROR(VLOOKUP(A12,MASTER!A:P,16,0),0) -> 0 | K12: =IFERROR(I12/J12-1,0) -> 0 | L12: =IFERROR(VLOOKUP(A12,MASTER!A:S,19,0),0) -> 0 | M12: =IFERROR(VLOOKUP(A12,MASTER!A:T,20,0),0) -> 0 | N12: =IFERROR(L12/M12-1,0) -> 0 | O12: =IFERROR(VLOOKUP(A12,MASTER!A:U,21,0),0) -> 0 | P12: =IFERROR(VLOOKUP(A12,MASTER!A:V,22,0),0) -> 0 | Q12: =IFERROR(O12/P12-1,0) -> 0 | R12: =IFERROR(VLOOKUP(A12,MASTER!A:W,23,0),0) -> 0 | S12: =IFERROR(VLOOKUP(A12,MASTER!A:X,24,0),0) -> 0 | T12: =IFERROR(R12/S12-1,0) -> 0 | U12: =IFERROR(VLOOKUP(A12,MASTER!A:M,13,0),0) -> 0 | V12: =IFERROR(VLOOKUP(A12,MASTER!A:N,14,0),0) -> 0 | W12: =IFERROR(U12/V12-1,0) -> 0 | X12: =IFERROR(VLOOKUP(A12,MASTER!A:Q,17,0),0) -> 0 | Y12: =IFERROR(VLOOKUP(A12,MASTER!A:R,18,0),0) -> 0 | Z12: =IFERROR(X12/Y12-1,0) -> 0
A13: SUTI SEMARANG|BENGKAYANG | B13: SDP JAGOI BABANG | C13: =IFERROR(VLOOKUP(A:A,MASTER!A:C,3,0),0) -> 0 | D13: =IFERROR(VLOOKUP(A:A,MASTER!A:D,4,0),0) -> 0 | E13: =IFERROR(C13/D13-1,0) -> 0 | F13: =IFERROR(VLOOKUP(A13,MASTER!A:E,5,0),0) -> 0 | G13: =IFERROR(VLOOKUP(A13,MASTER!A:F,6,0),0) -> 3378378.4 | H13: =IFERROR(F13/G13-1,0) -> -1 | I13: =IFERROR(VLOOKUP(A13,MASTER!A:O,15,0),0) -> 1.0233806e+08 | J13: =IFERROR(VLOOKUP(A13,MASTER!A:P,16,0),0) -> 48681081 | K13: =IFERROR(I13/J13-1,0) -> 1.1022143 | L13: =IFERROR(VLOOKUP(A13,MASTER!A:S,19,0),0) -> 0 | M13: =IFERROR(VLOOKUP(A13,MASTER!A:T,20,0),0) -> 0 | N13: =IFERROR(L13/M13-1,0) -> 0 | O13: =IFERROR(VLOOKUP(A13,MASTER!A:U,21,0),0) -> 0 | P13: =IFERROR(VLOOKUP(A13,MASTER!A:V,22,0),0) -> 0 | Q13: =IFERROR(O13/P13-1,0) -> 0 | R13: =IFERROR(VLOOKUP(A13,MASTER!A:W,23,0),0) -> 0 | S13: =IFERROR(VLOOKUP(A13,MASTER!A:X,24,0),0) -> 0 | T13: =IFERROR(R13/S13-1,0) -> 0 | U13: =IFERROR(VLOOKUP(A13,MASTER!A:M,13,0),0) -> 0 | V13: =IFERROR(VLOOKUP(A13,MASTER!A:N,14,0),0) -> 0 | W13: =IFERROR(U13/V13-1,0) -> 0 | X13: =IFERROR(VLOOKUP(A13,MASTER!A:Q,17,0),0) -> 0 | Y13: =IFERROR(VLOOKUP(A13,MASTER!A:R,18,0),0) -> 0 | Z13: =IFERROR(X13/Y13-1,0) -> 0
A14: TERIAK|BENGKAYANG | B14: SDP JAGOI BABANG | C14: =IFERROR(VLOOKUP(A:A,MASTER!A:C,3,0),0) -> 5.8792288e+08 | D14: =IFERROR(VLOOKUP(A:A,MASTER!A:D,4,0),0) -> 6.1783338e+08 | E14: =IFERROR(C14/D14-1,0) -> -0.048411913 | F14: =IFERROR(VLOOKUP(A14,MASTER!A:E,5,0),0) -> 70581795 | G14: =IFERROR(VLOOKUP(A14,MASTER!A:F,6,0),0) -> 21974599 | H14: =IFERROR(F14/G14-1,0) -> 2.2119719 | I14: =IFERROR(VLOOKUP(A14,MASTER!A:O,15,0),0) -> 1.3703707e+08 | J14: =IFERROR(VLOOKUP(A14,MASTER!A:P,16,0),0) -> 2.2861775e+08 | K14: =IFERROR(I14/J14-1,0) -> -0.40058431 | L14: =IFERROR(VLOOKUP(A14,MASTER!A:S,19,0),0) -> 3.1396098e+08 | M14: =IFERROR(VLOOKUP(A14,MASTER!A:T,20,0),0) -> 3.2519765e+08 | N14: =IFERROR(L14/M14-1,0) -> -0.034553345 | O14: =IFERROR(VLOOKUP(A14,MASTER!A:U,21,0),0) -> 1.1947746e+08 | P14: =IFERROR(VLOOKUP(A14,MASTER!A:V,22,0),0) -> 2.1927602e+08 | Q14: =IFERROR(O14/P14-1,0) -> -0.45512756 | R14: =IFERROR(VLOOKUP(A14,MASTER!A:W,23,0),0) -> 11285.577 | S14: =IFERROR(VLOOKUP(A14,MASTER!A:X,24,0),0) -> 11420.308 | T14: =IFERROR(R14/S14-1,0) -> -0.011797473 | U14: =IFERROR(VLOOKUP(A14,MASTER!A:M,13,0),0) -> 906 | V14: =IFERROR(VLOOKUP(A14,MASTER!A:N,14,0),0) -> 831 | W14: =IFERROR(U14/V14-1,0) -> 0.090252708 | X14: =IFERROR(VLOOKUP(A14,MASTER!A:Q,17,0),0) -> 350 | Y14: =IFERROR(VLOOKUP(A14,MASTER!A:R,18,0),0) -> 778 | Z14: =IFERROR(X14/Y14-1,0) -> -0.55012853
A15: TUJUH BELAS|BENGKAYANG | B15: SDP JAGOI BABANG | C15: =IFERROR(VLOOKUP(A:A,MASTER!A:C,3,0),0) -> 2.3661217e+08 | D15: =IFERROR(VLOOKUP(A:A,MASTER!A:D,4,0),0) -> 2.3157547e+08 | E15: =IFERROR(C15/D15-1,0) -> 0.021749675 | F15: =IFERROR(VLOOKUP(A15,MASTER!A:E,5,0),0) -> 1595450.5 | G15: =IFERROR(VLOOKUP(A15,MASTER!A:F,6,0),0) -> 118018.02 | H15: =IFERROR(F15/G15-1,0) -> 12.518702 | I15: =IFERROR(VLOOKUP(A15,MASTER!A:O,15,0),0) -> 21692207 | J15: =IFERROR(VLOOKUP(A15,MASTER!A:P,16,0),0) -> 25018739 | K15: =IFERROR(I15/J15-1,0) -> -0.1329616 | L15: =IFERROR(VLOOKUP(A15,MASTER!A:S,19,0),0) -> 74144865 | M15: =IFERROR(VLOOKUP(A15,MASTER!A:T,20,0),0) -> 74611140 | N15: =IFERROR(L15/M15-1,0) -> -0.0062493989 | O15: =IFERROR(VLOOKUP(A15,MASTER!A:U,21,0),0) -> 20895946 | P15: =IFERROR(VLOOKUP(A15,MASTER!A:V,22,0),0) -> 27697387 | Q15: =IFERROR(O15/P15-1,0) -> -0.24556256 | R15: =IFERROR(VLOOKUP(A15,MASTER!A:W,23,0),0) -> 4225.4615 | S15: =IFERROR(VLOOKUP(A15,MASTER!A:X,24,0),0) -> 4232.0769 | T15: =IFERROR(R15/S15-1,0) -> -0.0015631532 | U15: =IFERROR(VLOOKUP(A15,MASTER!A:M,13,0),0) -> 86 | V15: =IFERROR(VLOOKUP(A15,MASTER!A:N,14,0),0) -> 25 | W15: =IFERROR(U15/V15-1,0) -> 2.44 | X15: =IFERROR(VLOOKUP(A15,MASTER!A:Q,17,0),0) -> 79 | Y15: =IFERROR(VLOOKUP(A15,MASTER!A:R,18,0),0) -> 202 | Z15: =IFERROR(X15/Y15-1,0) -> -0.60891089

Sheet MASTER
A2: parameter | B2: DD | C2: Prepaid Rev | D2: Prepaid Rev | E2: Primary | F2: Primary | G2: QSC 100MB | H2: QSC 100MB | I2: RETTAG_3GB | J2: RETTAG_3GB | K2: RGUGA FWA ALL CHANNEL | L2: RGUGA FWA ALL CHANNEL | M2: RGUGA-Trad | N2: RGUGA-Trad | O2: Secondary | P2: Secondary | Q2: SELLIN_3GB | R2: SELLIN_3GB | S2: Tertiary B# | T2: Tertiary B# | U2: Trade Supply | V2: Trade Supply | W2: VLR_SUBS | X2: VLR_SUBS
A3: kec_unik | B3: pt_id | C3: MTD | D3: LMTD | E3: MTD | F3: LMTD | G3: MTD | H3: LMTD | I3: MTD | J3: LMTD | K3: MTD | L3: LMTD | M3: MTD | N3: LMTD | O3: MTD | P3: LMTD | Q3: MTD | R3: LMTD | S3: MTD | T3: LMTD | U3: MTD | V3: LMTD | W3: MTD | X3: LMTD
A4: 2 X 11 KAYU TANAM|PADANG PARIAMAN | B4: PT-PARIAMAN | C4: 1.4415394e+08 | D4: 1.4605921e+08 | E4: 13513.514 | F4: 293693.69 | G4: 16 | H4: 17 | I4: 3 | J4: 2 | M4: 42 | N4: 32 | O4: 23376126 | P4: 68846667 | Q4: 98 | R4: 198 | S4: 35098189 | T4: 38066534 | U4: 7062522.5 | V4: 46766396 | W4: 2609.7692 | X4: 2767.2692
A5: 2X11 ENAM LINGKUNG|PADANG PARIAMAN | B5: PT-PARIAMAN | C5: 2.2345197e+08 | D5: 2.2596672e+08 | E5: 189189.19 | F5: 354054.05 | G5: 4 | H5: 3 | I5: 2 | J5: 5 | K5: 1 | M5: 125 | N5: 31 | O5: 31399550 | P5: 81901847 | Q5: 105 | R5: 227 | S5: 77163329 | T5: 81294261 | U5: 13553694 | V5: 54936126 | W5: 2872.1923 | X5: 3020.7308
A6: ABAB|PENUKAL ABAB LEMATANG ILIR | B6: PT-PRABUMULIH TANAH ABANG | C6: 3.0723377e+08 | D6: 3.5836048e+08 | E6: 1601786.5 | F6: 1531302.7 | G6: 134 | H6: 81 | I6: 4 | J6: 1 | K6: 1 | M6: 151 | N6: 89 | O6: 9086486.5 | P6: 4609729.7 | Q6: 55 | R6: 17 | S6: 55350464 | T6: 63230842 | U6: 9001351.4 | V6: 5958648.6 | W6: 4289.4615 | X6: 4751.8077
A7: ABANG|KARANGASEM | B7: PT-KARANGASEM TIMUR | C7: 7.2470279e+08 | D7: 7.0322883e+08 | E7: 75194505 | F7: 40134234 | G7: 178 | H7: 205 | I7: 14 | J7: 16 | M7: 204 | N7: 239 | O7: 1.9615405e+08 | P7: 2.2149437e+08 | Q7: 176 | R7: 690 | S7: 3.4571892e+08 | T7: 3.5603055e+08 | U7: 1.6430712e+08 | V7: 1.6599541e+08 | W7: 18402.692 | X7: 20269.923
A8: ABELI|KOTA KENDARI | B8: PT-KENDARI | C8: 1.8230535e+08 | D8: 1.8324428e+08 | E8: 2039891.9 | F8: 778378.38 | G8: 50 | H8: 62 | I8: 17 | J8: 17 | M8: 82 | N8: 109 | O8: 40651784 | P8: 41724865 | Q8: 246 | R8: 314 | S8: 61956554 | T8: 65698947 | U8: 44542342 | V8: 44338108 | W8: 3803.9615 | X8: 3825.9615
A9: ABEPURA|KOTA JAYAPURA | B9: PT-JAYAPURA UTARA | C9: 4.3200357e+08 | D9: 4.1733916e+08 | E9: 900900.9 | F9: 809009.01 | G9: 173 | H9: 214 | I9: 18 | J9: 13 | K9: 4 | M9: 291 | N9: 243 | O9: 47258378 | P9: 14869369 | Q9: 159 | R9: 214 | S9: 41522187 | T9: 39892377 | U9: 40494995 | V9: 14196079 | W9: 6318.8462 | X9: 6008.4231
A10: ABIANSEMAL|BADUNG | B10: PT-BADUNG | C10: 1.2054812e+09 | D10: 1.1709051e+09 | E10: 16235135 | F10: 2804955 | G10: 296 | H10: 279 | I10: 42 | J10: 52 | K10: 2 | M10: 534 | N10: 475 | O10: 2.3842072e+08 | P10: 2.2566486e+08 | Q10: 1483 | R10: 762 | S10: 3.2666868e+08 | T10: 3.2386859e+08 | U10: 2.203636e+08 | V10: 2.0539414e+08 | W10: 26035.538 | X10: 25274.923
A11: ABUKI|KONAWE | B11: PT-NORTH KONAWE | C11: 2.3808151e+08 | D11: 2.2733318e+08 | E11: 2878945.9 | F11: 229729.73 | G11: 97 | H11: 36 | I11: 19 | J11: 6 | M11: 279 | N11: 104 | O11: 37879396 | P11: 36011036 | Q11: 153 | R11: 85 | S11: 87829036 | T11: 81051703 | U11: 37634685 | V11: 33882207 | W11: 4212.6154 | X11: 4169
A12: ABUNG BARAT|LAMPUNG UTARA | B12: PT-KOTABUMI | C12: 3.5638599e+08 | D12: 3.9693452e+08 | E12: 2.870114e+08 | F12: 1379279.3 | G12: 80 | H12: 58 | I12: 14 | J12: 6 | K12: 1 | M12: 91 | N12: 109 | O12: 54453243 | P12: 56821081 | Q12: 361 | R12: 223 | S12: 1.2301737e+08 | T12: 1.3266922e+08 | U12: 57323063 | V12: 55229279 | W12: 5804.4231 | X12: 5981.3077
A13: ABUNG KUNANG|LAMPUNG UTARA | B13: PT-KOTABUMI | C13: 98290597 | D13: 1.019126e+08 | E13: 170945.95 | F13: 58558.559 | G13: 27 | H13: 29 | I13: 3 | J13: 3 | M13: 30 | N13: 33 | O13: 5145495.5 | P13: 3246846.8 | Q13: 161 | R13: 50 | S13: 31171117 | T13: 32238014 | U13: 5749369.4 | V13: 3812432.4 | W13: 1710.8077 | X13: 1676.9231
A14: ABUNG PEKURUN|LAMPUNG UTARA | B14: PT-KOTABUMI | C14: 1.1648181e+08 | D14: 1.2038776e+08 | E14: 9909.9099 | F14: 5405.4054 | G14: 38 | H14: 41 | I14: 2 | J14: 0 | M14: 42 | N14: 47 | O14: 3829729.7 | P14: 1605045 | Q14: 58 | R14: 12 | S14: 30087622 | T14: 31589685 | U14: 2849549.5 | V14: 1434864.9 | W14: 1900.2692 | X14: 1878.3077
A15: ABUNG SELATAN|LAMPUNG UTARA | B15: PT-KOTABUMI | C15: 9.0037788e+08 | D15: 1.066705e+09 | E15: 8648198.2 | F15: 1406306.3 | G15: 213 | H15: 121 | I15: 18 | J15: 23 | K15: 3 | M15: 344 | N15: 370 | O15: 76437568 | P15: 62283919 | Q15: 444 | R15: 432 | S15: 2.7276719e+08 | T15: 2.7981606e+08 | U15: 79770360 | V15: 62748108 | W15: 16182.846 | X15: 16106.077
A16: ABUNG SEMULI|LAMPUNG UTARA | B16: PT-SUNGKAI | C16: 3.7576081e+08 | D16: 3.9886216e+08 | E16: 4415936.9 | F16: 192792.79 | G16: 90 | H16: 64 | I16: 17 | J16: 16 | K16: 3 | M16: 116 | N16: 75 | O16: 48295225 | P16: 44340360 | Q16: 176 | R16: 267 | S16: 90211356 | T16: 97506359 | U16: 49370090 | V16: 39253333 | W16: 6140.3462 | X16: 6158.8846
A17: ABUNG SURAKARTA|LAMPUNG UTARA | B17: PT-LAMPUNG UTARA ABUNG SEMULI | C17: 5.6649978e+08 | D17: 6.0414871e+08 | E17: 1.6283765e+08 | F17: 1.8012901e+08 | G17: 112 | H17: 108 | I17: 24 | J17: 21 | K17: 2 | M17: 138 | N17: 163 | O17: 1.5782191e+08 | P17: 1.6956754e+08 | Q17: 175 | R17: 347 | S17: 1.3893649e+08 | T17: 1.4779228e+08 | U17: 1.4424009e+08 | V17: 1.5622396e+08 | W17: 9085.8846 | X17: 9441.6538
A18: ABUNG TENGAH|LAMPUNG UTARA | B18: PT-KOTABUMI | C18: 1.6570003e+08 | D18: 1.9010661e+08 | E18: 2375405.4 | F18: 349324.32 | G18: 51 | H18: 47 | I18: 7 | J18: 4 | K18: 1 | M18: 61 | N18: 62 | O18: 21410360 | P18: 23249144 | Q18: 160 | R18: 143 | S18: 56141491 | T18: 61791473 | U18: 19505586 | V18: 18218288 | W18: 3094.2692 | X18: 3131.5
A19: ABUNG TIMUR|LAMPUNG UTARA | B19: PT-SUNGKAI | C19: 4.6206015e+08 | D19: 4.9064936e+08 | E19: 6580630.6 | F19: 2190991 | G19: 263 | H19: 204 | I19: 10 | J19: 7 | K19: 3 | M19: 287 | N19: 228 | O19: 31848108 | P19: 30827027 | Q19: 129 | R19: 191 | S19: 1.0746025e+08 | T19: 1.1370211e+08 | U19: 29998061 | V19: 31585405 | W19: 7214.6923 | X19: 6916.5769
A20: ABUNG TINGGI|LAMPUNG UTARA | B20: PT-TANJUNG RAJA | C20: 2.6634169e+08 | D20: 2.9436145e+08 | E20: 35810.811 | F20: 229729.73 | G20: 81 | H20: 79 | I20: 6 | J20: 8 | K20: 3 | M20: 97 | N20: 100 | O20: 58712613 | P20: 39812252 | Q20: 108 | R20: 137 | S20: 52643216 | T20: 59695084 | U20: 58140541 | V20: 40126577 | W20: 4529.9615 | X20: 4649.6923
A21: ADILUWIH|PRINGSEWU | B21: PT-ADILUWIH | C21: 2.2384274e+08 | D21: 2.4260438e+08 | E21: 64130375 | F21: 69551862 | G21: 53 | H21: 95 | I21: 2 | J21: 11 | M21: 75 | N21: 190 | O21: 45464054 | P21: 49822162 | R21: 175 | S21: 71228548 | T21: 74970383 | U21: 34843423 | V21: 36163964 | W21: 7503.3077 | X21: 7408.2308
A22: ADIMULYO|KEBUMEN | B22: PT-KEBUMEN BARAT | C22: 1.2029692e+08 | D22: 1.2099313e+08 | E22: 120720.72 | F22: 32432.432 | G22: 68 | H22: 14 | I22: 6 | J22: 4 | K22: 3 | M22: 89 | N22: 33 | O22: 5348378.4 | P22: 7939189.2 | Q22: 87 | R22: 89 | S22: 28419027 | T22: 29290604 | U22: 4472342.3 | V22: 5508468.5 | W22: 3200.7692 | X22: 3342.0769
A23: ADIPALA|CILACAP | B23: PT-CILACAP TIMUR | C23: 9.991047e+08 | D23: 1.0007173e+09 | E23: 7879054.1 | F23: 667342.34 | G23: 288 | H23: 359 | I23: 35 | J23: 29 | K23: 2 | M23: 487 | N23: 489 | O23: 3.4639831e+08 | P23: 2.9756005e+08 | Q23: 837 | R23: 1001 | S23: 3.2046153e+08 | T23: 3.2984357e+08 | U23: 89346486 | V23: 1.3972545e+08 | W23: 28140.462 | X23: 27790.423
A24: ADIWERNA|TEGAL | B24: PT-TEGAL BARAT | C24: 1.6867119e+09 | D24: 1.7064416e+09 | E24: 5.6854293e+08 | F24: 58196509 | G24: 472 | H24: 295 | I24: 41 | J24: 37 | M24: 813 | N24: 568 | O24: 3.4983098e+08 | P24: 9.0841126e+08 | Q24: 724 | R24: 1571 | S24: 6.042808e+08 | T24: 6.1753357e+08 | U24: 1.5211712e+08 | V24: 8.1298306e+08 | W24: 43758.231 | X24: 43886.615
A25: ADONARA BARAT|FLORES TIMUR | B25: PT-ADONARA | C25: 7017933.7 | D25: 8562627.9 | M25: 3 | N25: 8 | O25: 208108.11 | P25: 209909.91 | Q25: 18 | R25: 2 | S25: 960108.11 | T25: 1521891.9 | U25: 259459.46 | V25: 106306.31 | W25: 141.73077 | X25: 149.26923
A26: ADONARA BARAT|FLORES TIMUR | B26: PT-ADONARA TIMUR | C26: 26146039 | D26: 24305569 | E26: 62612.613 | F26: 166666.67 | G26: 14 | H26: 9 | I26: 2 | J26: 0 | M26: 14 | N26: 10 | O26: 2855135.1 | P26: 2954054.1 | Q26: 31 | R26: 32 | S26: 6448331.5 | T26: 5777387.4 | U26: 2197297.3 | V26: 2357477.5 | W26: 394 | X26: 391
A27: ADONARA TENGAH|FLORES TIMUR | B27: PT-ADONARA | C27: 19623451 | D27: 16301721 | M27: 53 | N27: 5 | O27: 232432.43 | P27: 479279.28 | Q27: 10 | R27: 2 | S27: 4198058.6 | T27: 2493626.1 | U27: 239189.19 | V27: 587387.39 | W27: 244.30769 | X27: 228.96154
A28: ADONARA TENGAH|FLORES TIMUR | B28: PT-ADONARA TIMUR | C28: 52587923 | D28: 28813596 | E28: 131081.08 | F28: 66666.667 | G28: 225 | H28: 13 | I28: 3 | J28: 2 | M28: 228 | N28: 16 | O28: 7285405.4 | P28: 3103603.6 | Q28: 52 | R28: 19 | S28: 15073153 | T28: 6654864.9 | U28: 2428288.3 | V28: 1211621.6 | W28: 677 | X28: 434
A29: ADONARA TIMUR|FLORES TIMUR | B29: PT-ADONARA | C29: 93849064 | D29: 87026335 | M29: 259 | N29: 54 | O29: 14177477 | P29: 8056180.2 | Q29: 142 | R29: 18 | S29: 24795841 | T29: 16323662 | U29: 9242973 | V29: 4793423.4 | W29: 1284.9615 | X29: 1324
A30: ADONARA TIMUR|FLORES TIMUR | B30: PT-ADONARA TIMUR | C30: 94987714 | D30: 77850083 | E30: 35281532 | F30: 24897470 | G30: 205 | H30: 32 | I30: 12 | J30: 9 | M30: 215 | N30: 33 | O30: 22307207 | P30: 15822523 | Q30: 196 | R30: 70 | S30: 19156126 | T30: 14152881 | U30: 12062883 | V30: 8078198.2 | W30: 1185 | X30: 1130
A31: ADONARA|FLORES TIMUR | B31: PT-ADONARA | C31: 1.1282366e+08 | D31: 1.1597935e+08 | E31: 58146200 | F31: 34282859 | M31: 189 | N31: 57 | O31: 22301802 | P31: 15468306 | Q31: 221 | R31: 26 | S31: 26762086 | T31: 23620324 | U31: 7413964 | V31: 5783333.3 | W31: 1367.4615 | X31: 1405.5769
A32: ADONARA|FLORES TIMUR | B32: PT-ADONARA TIMUR | C32: 45047373 | D32: 38699287 | E32: 11711.712 | F32: 8108.1081 | G32: 42 | H32: 8 | I32: 13 | J32: 4 | M32: 42 | N32: 8 | O32: 2257837.8 | P32: 1593693.7 | Q32: 37 | R32: 24 | S32: 8233108.1 | T32: 7633964 | U32: 2010180.2 | V32: 1539459.5 | W32: 536 | X32: 515
A33: AEK KUASAN|ASAHAN | B33: PT-TANJUNG BALAI | C33: 68709457 | D33: 67993640 | G33: 16 | H33: 6 | I33: 0 | J33: 0 | M33: 25 | N33: 13 | O33: 3310810.8 | P33: 4307207.2 | Q33: 2 | R33: 18 | S33: 19592446 | T33: 18812644 | U33: 3037387.4 | V33: 5887117.1 | W33: 1316.0385 | X33: 1330.4231
A34: AEK KUO|LABUHANBATU UTARA | B34: PT-LABURA | C34: 1.6521204e+08 | D34: 1.5737477e+08 | E34: 1952252.3 | F34: 2224324.3 | G34: 14 | H34: 13 | I34: 2 | J34: 0 | M34: 31 | N34: 19 | O34: 8807657.7 | P34: 6999639.6 | Q34: 40 | R34: 56 | S34: 60800356 | T34: 60031286 | U34: 8518918.9 | V34: 7260000 | W34: 2719.0385 | X34: 2717.2692
A35: AEK LEDONG|ASAHAN | B35: PT-TANJUNG BALAI | C35: 89374559 | D35: 91317649 | E35: 900.9009 | F35: 1.4616036e+08 | G35: 10 | H35: 6 | I35: 0 | J35: 0 | M35: 20 | N35: 17 | O35: 9608108.1 | P35: 12341441 | R35: 107 | S35: 25436009 | T35: 28716261 | U35: 1067207.2 | V35: 6139729.7 | W35: 1975.6154 | X35: 2055.9231
A36: AEK NABARA BARUMUN|PADANG LAWAS | B36: PT-PADANG LAWAS | C36: 57043881 | D36: 58588748 | E36: 137837.84 | F36: 1801.8018 | G36: 19 | H36: 48 | I36: 0 | J36: 0 | K36: 1 | M36: 33 | N36: 63 | O36: 3128738.7 | P36: 1929729.7 | Q36: 9 | R36: 16 | S36: 17188559 | T36: 20134950 | U36: 2320360.4 | V36: 1558828.8 | W36: 1083.2308 | X36: 1094.5385
A37: AEK NATAS|LABUHANBATU UTARA | B37: PT-LABURA | C37: 73936298 | D37: 70692663 | E37: 25225.225 | F37: 17117.117 | G37: 27 | H37: 4 | I37: 4 | J37: 2 | M37: 43 | N37: 9 | O37: 14987387 | P37: 10790991 | Q37: 22 | R37: 50 | S37: 26663446 | T37: 25899212 | U37: 14612793 | V37: 13287568 | W37: 1669.7692 | X37: 1661.8846
A38: AEK SONGSONGAN|ASAHAN | B38: PT-TANJUNG BALAI | C38: 22982175 | D38: 22861479 | E38: 900.9009 | F38: 7207.2072 | G38: 3 | H38: 2 | I38: 1 | J38: 1 | M38: 18 | N38: 20 | O38: 3513513.5 | P38: 3125225.2 | Q38: 1 | R38: 9 | S38: 17176369 | T38: 16076342 | U38: 2806756.8 | V38: 3098828.8 | W38: 515.23077 | X38: 505.69231
A39: AERE|KOLAKA TIMUR | B39: PT-TANGGETADA | C39: 11120898 | D39: 9683323.8 | G39: 4 | H39: 10 | M39: 7 | N39: 15 | S39: 1104941.4 | T39: 1817504.5 | W39: 189.07692 | X39: 206.11538
A40: AERTEMBAGA|KOTA BITUNG | B40: PT-BITUNG | C40: 4.2853325e+08 | D40: 4.1318882e+08 | E40: 29850450 | F40: 1.1381419e+08 | G40: 12 | H40: 5 | I40: 2 | J40: 2 | K40: 1 | M40: 400 | N40: 150 | O40: 33692703 | P40: 30961081 | Q40: 3 | R40: 493 | S40: 1.3524421e+08 | T40: 1.3536248e+08 | U40: 20722072 | V40: 30701351 | W40: 6255.1154 | X40: 6122.4615
A41: AESESA|NAGEKEO | B41: PT-AESESA | C41: 3.2208223e+08 | D41: 3.1398515e+08 | E41: 65461617 | F41: 68260403 | G41: 97 | H41: 134 | I41: 8 | J41: 27 | K41: 2 | M41: 198 | N41: 258 | O41: 70473874 | P41: 71035778 | Q41: 339 | R41: 328 | S41: 79676228 | T41: 77522095 | U41: 56682295 | V41: 53520000 | W41: 4640.8462 | X41: 4451.3077
...
