Workbook

Sheet Sheet1
A1: SITE ID | B1: SITE NAME | C1: PARTNER | D1: DSE CODE | E1: CATEGORY | F1: REVENUE LMTD | G1: REVENUE MTD | H1: GROWTH | I1: VLR LMTD | J1: VLR MTD | K1: GROWTH | L1: FWA VLR LMTD | M1: FWA VLR MTD | N1: GROWTH | O1: RGU GA LMTD | P1: RGU GA MTD | Q1: GROWTH | R1: RGU 90D LMTD | S1: RGU 90D MTD | T1: GROWTH | U1: OUTLET OKTOBER
A2: 20BEK0032 | B2: TIRTA_KENCANA_BEK_PL | C2: PT-JAGOI BABANG | D2: DSEKL087 | E2: PROFIT | F2: =VLOOKUP(A:A,MASTER!A:F,6,0) -> 85856257 | G2: =VLOOKUP(A:A,MASTER!A:K,11,0) -> 8853969 | H2: =IFERROR(G2/F2-1,0) -> -0.89687451 | I2: =VLOOKUP(A:A,MASTER!A:E,5,0) -> 1297 | J2: =VLOOKUP(A:A,MASTER!A:J,10,0) -> 1287 | K2: =IFERROR(J2/I2-1,0) -> -0.0077101002 | L2: =VLOOKUP(A:A,MASTER!A:D,4,0) -> 3 | M2: =VLOOKUP(A:A,MASTER!A:I,9,0) -> 4 | N2: =IFERROR(M2/L2-1,0) -> 0.33333333 | O2: =VLOOKUP(A:A,MASTER!A:C,3,0) -> 9 | P2: =VLOOKUP(A:A,MASTER!A:H,8,0) -> 10 | Q2: =IFERROR(P2/O2-1,0) -> 0.11111111 | R2: =VLOOKUP(A:A,MASTER!A:B,2,0) -> 2895 | S2: =VLOOKUP(A:A,MASTER!A:G,7,0) -> 3049 | T2: =IFERROR(S2/R2-1,0) -> 0.053195164 | U2: 4
A3: 20BEK0033 | B3: DESA_CIPTAKARYA_BEK_PL | C3: PT-JAGOI BABANG | D3: DSEKL088 | E3: PROFIT | F3: =VLOOKUP(A:A,MASTER!A:F,6,0) -> 42426650 | G3: =VLOOKUP(A:A,MASTER!A:K,11,0) -> 3963028.6 | H3: =IFERROR(G3/F3-1,0) -> -0.90659105 | I3: =VLOOKUP(A:A,MASTER!A:E,5,0) -> 789 | J3: =VLOOKUP(A:A,MASTER!A:J,10,0) -> 611 | K3: =IFERROR(J3/I3-1,0) -> -0.22560203 | L3: =VLOOKUP(A:A,MASTER!A:D,4,0) -> 4 | M3: =VLOOKUP(A:A,MASTER!A:I,9,0) -> 3 | N3: =IFERROR(M3/L3-1,0) -> -0.25 | O3: =VLOOKUP(A:A,MASTER!A:C,3,0) -> 5 | P3: =VLOOKUP(A:A,MASTER!A:H,8,0) -> 1 | Q3: =IFERROR(P3/O3-1,0) -> -0.8 | R3: =VLOOKUP(A:A,MASTER!A:B,2,0) -> 1606 | S3: =VLOOKUP(A:A,MASTER!A:G,7,0) -> 1384 | T3: =IFERROR(S3/R3-1,0) -> -0.13823163 | U3: 3
A4: 20BEK0034 | B4: LUMAR_MT | C4: PT-JAGOI BABANG | D4: DSEKL513 | E4: PROFIT | F4: =VLOOKUP(A:A,MASTER!A:F,6,0) -> 91250280 | G4: =VLOOKUP(A:A,MASTER!A:K,11,0) -> 3806414 | H4: =IFERROR(G4/F4-1,0) -> -0.958286 | I4: =VLOOKUP(A:A,MASTER!A:E,5,0) -> 1637 | J4: =VLOOKUP(A:A,MASTER!A:J,10,0) -> 1631 | K4: =IFERROR(J4/I4-1,0) -> -0.0036652413 | L4: =VLOOKUP(A:A,MASTER!A:D,4,0) -> 9 | M4: =VLOOKUP(A:A,MASTER!A:I,9,0) -> 11 | N4: =IFERROR(M4/L4-1,0) -> 0.22222222 | O4: =VLOOKUP(A:A,MASTER!A:C,3,0) -> 7 | P4: =VLOOKUP(A:A,MASTER!A:H,8,0) -> 12 | Q4: =IFERROR(P4/O4-1,0) -> 0.71428571 | R4: =VLOOKUP(A:A,MASTER!A:B,2,0) -> 3701 | S4: =VLOOKUP(A:A,MASTER!A:G,7,0) -> 3747 | T4: =IFERROR(S4/R4-1,0) -> 0.012429073 | U4: 5
A5: 20BEK0035 | B5: JELAYAN_TERIAK_BEK_MT | C5: PT-JAGOI BABANG | D5: DSEKL087 | E5: PROFIT | F5: =VLOOKUP(A:A,MASTER!A:F,6,0) -> 57261577 | G5: =VLOOKUP(A:A,MASTER!A:K,11,0) -> 19213672 | H5: =IFERROR(G5/F5-1,0) -> -0.66445786 | I5: =VLOOKUP(A:A,MASTER!A:E,5,0) -> 1093 | J5: =VLOOKUP(A:A,MASTER!A:J,10,0) -> 988 | K5: =IFERROR(J5/I5-1,0) -> -0.096065874 | L5: =VLOOKUP(A:A,MASTER!A:D,4,0) -> 5 | M5: =VLOOKUP(A:A,MASTER!A:I,9,0) -> 5 | N5: =IFERROR(M5/L5-1,0) -> 0 | O5: =VLOOKUP(A:A,MASTER!A:C,3,0) -> 10 | P5: =VLOOKUP(A:A,MASTER!A:H,8,0) -> 5 | Q5: =IFERROR(P5/O5-1,0) -> -0.5 | R5: =VLOOKUP(A:A,MASTER!A:B,2,0) -> 2059 | S5: =VLOOKUP(A:A,MASTER!A:G,7,0) -> 2026 | T5: =IFERROR(S5/R5-1,0) -> -0.016027198 | U5: 3
A6: 20BEK0036 | B6: BUMI_MAS_PL | C6: PT-JAGOI BABANG | D6: DSEKL092 | E6: PROFIT | F6: =VLOOKUP(A:A,MASTER!A:F,6,0) -> 54982146 | G6: =VLOOKUP(A:A,MASTER!A:K,11,0) -> 26429961 | H6: =IFERROR(G6/F6-1,0) -> -0.51929921 | I6: =VLOOKUP(A:A,MASTER!A:E,5,0) -> 420 | J6: =VLOOKUP(A:A,MASTER!A:J,10,0) -> 1058 | K6: =IFERROR(J6/I6-1,0) -> 1.5190476 | L6: =VLOOKUP(A:A,MASTER!A:D,4,0) -> 2 | M6: =VLOOKUP(A:A,MASTER!A:I,9,0) -> 4 | N6: =IFERROR(M6/L6-1,0) -> 1 | O6: =VLOOKUP(A:A,MASTER!A:C,3,0) -> 9 | P6: =VLOOKUP(A:A,MASTER!A:H,8,0) -> 11 | Q6: =IFERROR(P6/O6-1,0) -> 0.22222222 | R6: =VLOOKUP(A:A,MASTER!A:B,2,0) -> 1456 | S6: =VLOOKUP(A:A,MASTER!A:G,7,0) -> 1924 | T6: =IFERROR(S6/R6-1,0) -> 0.32142857 | U6: 4
A7: 20BEK0037 | B7: BUMI_EMAS_BENGKAYANG_MT | C7: PT-JAGOI BABANG | D7: DSEKL092 | E7: PROFIT | F7: =VLOOKUP(A:A,MASTER!A:F,6,0) -> 1.1478376e+08 | G7: =VLOOKUP(A:A,MASTER!A:K,11,0) -> 51003532 | H7: =IFERROR(G7/F7-1,0) -> -0.55565551 | I7: =VLOOKUP(A:A,MASTER!A:E,5,0) -> 1956 | J7: =VLOOKUP(A:A,MASTER!A:J,10,0) -> 1791 | K7: =IFERROR(J7/I7-1,0) -> -0.084355828 | L7: =VLOOKUP(A:A,MASTER!A:D,4,0) -> 4 | M7: =VLOOKUP(A:A,MASTER!A:I,9,0) -> 5 | N7: =IFERROR(M7/L7-1,0) -> 0.25 | O7: =VLOOKUP(A:A,MASTER!A:C,3,0) -> 25 | P7: =VLOOKUP(A:A,MASTER!A:H,8,0) -> 24 | Q7: =IFERROR(P7/O7-1,0) -> -0.04 | R7: =VLOOKUP(A:A,MASTER!A:B,2,0) -> 3782 | S7: =VLOOKUP(A:A,MASTER!A:G,7,0) -> 3609 | T7: =IFERROR(S7/R7-1,0) -> -0.045742993 | U7: 13
A8: 20BEK0038 | B8: BUMI_EMAS_MT | C8: PT-JAGOI BABANG | D8: DSEKL092 | E8: PROFIT | F8: =VLOOKUP(A:A,MASTER!A:F,6,0) -> 81275206 | G8: =VLOOKUP(A:A,MASTER!A:K,11,0) -> 26694663 | H8: =IFERROR(G8/F8-1,0) -> -0.67155219 | I8: =VLOOKUP(A:A,MASTER!A:E,5,0) -> 1318 | J8: =VLOOKUP(A:A,MASTER!A:J,10,0) -> 1355 | K8: =IFERROR(J8/I8-1,0) -> 0.028072838 | L8: =VLOOKUP(A:A,MASTER!A:D,4,0) -> 4 | M8: =VLOOKUP(A:A,MASTER!A:I,9,0) -> 4 | N8: =IFERROR(M8/L8-1,0) -> 0 | O8: =VLOOKUP(A:A,MASTER!A:C,3,0) -> 938 | P8: =VLOOKUP(A:A,MASTER!A:H,8,0) -> 1017 | Q8: =IFERROR(P8/O8-1,0) -> 0.084221748 | R8: =VLOOKUP(A:A,MASTER!A:B,2,0) -> 3552 | S8: =VLOOKUP(A:A,MASTER!A:G,7,0) -> 4136 | T8: =IFERROR(S8/R8-1,0) -> 0.16441441 | U8: 4
A9: 20BEK0039 | B9: BENGKAYANG_MT | C9: PT-JAGOI BABANG | D9: DSEKL092 | E9: PROFIT | F9: =VLOOKUP(A:A,MASTER!A:F,6,0) -> 1.5571452e+08 | G9: =VLOOKUP(A:A,MASTER!A:K,11,0) -> 61680438 | H9: =IFERROR(G9/F9-1,0) -> -0.60388768 | I9: =VLOOKUP(A:A,MASTER!A:E,5,0) -> 2733 | J9: =VLOOKUP(A:A,MASTER!A:J,10,0) -> 2748 | K9: =IFERROR(J9/I9-1,0) -> 0.0054884742 | L9: =VLOOKUP(A:A,MASTER!A:D,4,0) -> 7 | M9: =VLOOKUP(A:A,MASTER!A:I,9,0) -> 8 | N9: =IFERROR(M9/L9-1,0) -> 0.14285714 | O9: =VLOOKUP(A:A,MASTER!A:C,3,0) -> 777 | P9: =VLOOKUP(A:A,MASTER!A:H,8,0) -> 982 | Q9: =IFERROR(P9/O9-1,0) -> 0.26383526 | R9: =VLOOKUP(A:A,MASTER!A:B,2,0) -> 6497 | S9: =VLOOKUP(A:A,MASTER!A:G,7,0) -> 6405 | T9: =IFERROR(S9/R9-1,0) -> -0.014160382 | U9: 16
A10: 20BEK0040 | B10: SEBALO_BEK_PL | C10: PT-JAGOI BABANG | D10: DSEKL513 | E10: LRS | F10: =VLOOKUP(A:A,MASTER!A:F,6,0) -> 39244405 | G10: =VLOOKUP(A:A,MASTER!A:K,11,0) -> 4689317.6 | H10: =IFERROR(G10/F10-1,0) -> -0.88050991 | I10: =VLOOKUP(A:A,MASTER!A:E,5,0) -> 495 | J10: =VLOOKUP(A:A,MASTER!A:J,10,0) -> 500 | K10: =IFERROR(J10/I10-1,0) -> 0.01010101 | L10: =VLOOKUP(A:A,MASTER!A:D,4,0) -> 11 | M10: =VLOOKUP(A:A,MASTER!A:I,9,0) -> 12 | N10: =IFERROR(M10/L10-1,0) -> 0.090909091 | O10: =VLOOKUP(A:A,MASTER!A:C,3,0) -> 3 | P10: =VLOOKUP(A:A,MASTER!A:H,8,0) -> 8 | Q10: =IFERROR(P10/O10-1,0) -> 1.6666667 | R10: =VLOOKUP(A:A,MASTER!A:B,2,0) -> 1160 | S10: =VLOOKUP(A:A,MASTER!A:G,7,0) -> 1242 | T10: =IFERROR(S10/R10-1,0) -> 0.070689655 | U10: 3
A11: 20BEK0041 | B11: TVRI_BUMI_AMAS_MT | C11: PT-JAGOI BABANG | D11: DSEKL092 | E11: PROFIT | F11: =VLOOKUP(A:A,MASTER!A:F,6,0) -> 1.3847483e+08 | G11: =VLOOKUP(A:A,MASTER!A:K,11,0) -> 32087167 | H11: =IFERROR(G11/F11-1,0) -> -0.7682816 | I11: =VLOOKUP(A:A,MASTER!A:E,5,0) -> 2827 | J11: =VLOOKUP(A:A,MASTER!A:J,10,0) -> 2713 | K11: =IFERROR(J11/I11-1,0) -> -0.040325433 | L11: =VLOOKUP(A:A,MASTER!A:D,4,0) -> 9 | M11: =VLOOKUP(A:A,MASTER!A:I,9,0) -> 10 | N11: =IFERROR(M11/L11-1,0) -> 0.11111111 | O11: =VLOOKUP(A:A,MASTER!A:C,3,0) -> 12 | P11: =VLOOKUP(A:A,MASTER!A:H,8,0) -> 11 | Q11: =IFERROR(P11/O11-1,0) -> -0.083333333 | R11: =VLOOKUP(A:A,MASTER!A:B,2,0) -> 5119 | S11: =VLOOKUP(A:A,MASTER!A:G,7,0) -> 5143 | T11: =IFERROR(S11/R11-1,0) -> 0.0046884157 | U11: 4
A12: 20BEK0042 | B12: BELIMBING_BEK_PL | C12: PT-JAGOI BABANG | D12: DSEKL513 | E12: PROFIT | F12: =VLOOKUP(A:A,MASTER!A:F,6,0) -> 85399762 | G12: =VLOOKUP(A:A,MASTER!A:K,11,0) -> 10226866 | H12: =IFERROR(G12/F12-1,0) -> -0.88024713 | I12: =VLOOKUP(A:A,MASTER!A:E,5,0) -> 907 | J12: =VLOOKUP(A:A,MASTER!A:J,10,0) -> 1107 | K12: =IFERROR(J12/I12-1,0) -> 0.22050717 | L12: =VLOOKUP(A:A,MASTER!A:D,4,0) -> 7 | M12: =VLOOKUP(A:A,MASTER!A:I,9,0) -> 7 | N12: =IFERROR(M12/L12-1,0) -> 0 | O12: =VLOOKUP(A:A,MASTER!A:C,3,0) -> 8 | P12: =VLOOKUP(A:A,MASTER!A:H,8,0) -> 12 | Q12: =IFERROR(P12/O12-1,0) -> 0.5 | R12: =VLOOKUP(A:A,MASTER!A:B,2,0) -> 2052 | S12: =VLOOKUP(A:A,MASTER!A:G,7,0) -> 2235 | T12: =IFERROR(S12/R12-1,0) -> 0.089181287 | U12: 3
A13: 20BEK0043 | B13: RANGKANG_BEK_EP | C13: PT-JAGOI BABANG | D13: DSEKL088 | E13: PROFIT | F13: =VLOOKUP(A:A,MASTER!A:F,6,0) -> 79222657 | G13: =VLOOKUP(A:A,MASTER!A:K,11,0) -> 21823936 | H13: =IFERROR(G13/F13-1,0) -> -0.72452405 | I13: =VLOOKUP(A:A,MASTER!A:E,5,0) -> 1541 | J13: =VLOOKUP(A:A,MASTER!A:J,10,0) -> 1340 | K13: =IFERROR(J13/I13-1,0) -> -0.13043478 | L13: =VLOOKUP(A:A,MASTER!A:D,4,0) -> 9 | M13: =VLOOKUP(A:A,MASTER!A:I,9,0) -> 13 | N13: =IFERROR(M13/L13-1,0) -> 0.44444444 | O13: =VLOOKUP(A:A,MASTER!A:C,3,0) -> 10 | P13: =VLOOKUP(A:A,MASTER!A:H,8,0) -> 5 | Q13: =IFERROR(P13/O13-1,0) -> -0.5 | R13: =VLOOKUP(A:A,MASTER!A:B,2,0) -> 2770 | S13: =VLOOKUP(A:A,MASTER!A:G,7,0) -> 2589 | T13: =IFERROR(S13/R13-1,0) -> -0.06534296 | U13: 4
... A46: 20BEK0093 | B46: SIMPANG_PAKET_MT | C46: PT-JAGOI BABANG | D46: DSEKL085 | E46: PROFIT | F46: =VLOOKUP(A:A,MASTER!A:F,6,0) -> 66235932 | G46: =VLOOKUP(A:A,MASTER!A:K,11,0) -> 16775505 | H46: =IFERROR(G46/F46-1,0) -> -0.74673105 | I46: =VLOOKUP(A:A,MASTER!A:E,5,0) -> 953 | J46: =VLOOKUP(A:A,MASTER!A:J,10,0) -> 808 | K46: =IFERROR(J46/I46-1,0) -> -0.1521511 | L46: =VLOOKUP(A:A,MASTER!A:D,4,0) -> 10 | M46: =VLOOKUP(A:A,MASTER!A:I,9,0) -> 10 | N46: =IFERROR(M46/L46-1,0) -> 0 | O46: =VLOOKUP(A:A,MASTER!A:C,3,0) -> 18 | P46: =VLOOKUP(A:A,MASTER!A:H,8,0) -> 13 | Q46: =IFERROR(P46/O46-1,0) -> -0.27777778 | R46: =VLOOKUP(A:A,MASTER!A:B,2,0) -> 1651 | S46: =VLOOKUP(A:A,MASTER!A:G,7,0) -> 1694 | T46: =IFERROR(S46/R46-1,0) -> 0.026044821 | U46: 7

Sheet MASTER
B3: =SUBTOTAL(9,B6:B90) -> 197145 | C3: =SUBTOTAL(9,C6:C90) -> 3984 | D3: =SUBTOTAL(9,D6:D90) -> 490 | E3: =SUBTOTAL(9,E6:E90) -> 92522 | F3: =SUBTOTAL(9,F6:F90) -> 5.633979e+09 | G3: =SUBTOTAL(9,G6:G90) -> 199934 | H3: =SUBTOTAL(9,H6:H90) -> 4730 | I3: =SUBTOTAL(9,I6:I90) -> 510 | ... K3: =SUBTOTAL(9,K6:K90) -> 1.2133858e+09
B4: lmtd | G4: mtd
A5: Row Labels | B5: Sum of RGU 90D | C5: Sum of RGU GA TRADE | D5: Sum of FWA VLR | E5: Sum of VLR SUBS | F5: Sum of PREPAID REVENUE NETT | G5: Sum of RGU 90D | H5: Sum of RGU GA TRADE | I5: Sum of FWA VLR | J5: Sum of VLR SUBS | K5: Sum of PREPAID REVENUE NETT
A6: 20BEK0001 | B6: 3649 | C6: 7 | D6: 4 | E6: 631 | F6: 26135431 | G6: 2987 | H6: 4 | I6: 3 | J6: 510 | K6: 5038447
A7: 20BEK0002 | B7: 1836 | C7: 9 | D7: 4 | E7: 735 | F7: 27236134 | G7: 1719 | H7: 10 | I7: 5 | J7: 936 | K7: 7674269.8
A8: 20BEK0003 | B8: 2353 | C8: 15 | D8: 2 | E8: 1318 | F8: 46942838 | G8: 2002 | H8: 9 | I8: 2 | J8: 560 | K8: 18045139
A9: 20BEK0004 | B9: 2820 | C9: 20 | D9: 3 | E9: 1185 | F9: 79239174 | G9: 2716 | H9: 14 | I9: 3 | J9: 1292 | K9: 23052151
A10: 20BEK0005 | B10: 1846 | C10: 10 | D10: 4 | E10: 1376 | F10: 72819721 | G10: 1778 | H10: 10 | I10: 4 | J10: 1317 | K10: 47293837
A11: 20BEK0006 | B11: 1314 | C11: 14 | D11: 8 | E11: 770 | F11: 53209831 | G11: 1286 | H11: 6 | I11: 8 | J11: 756 | K11: 33257185
A12: 20BEK0007 | B12: 2078 | C12: 23 | D12: 3 | E12: 1034 | F12: 51978652 | G12: 2157 | H12: 21 | I12: 2 | J12: 967 | K12: 28476167
A13: 20BEK0008 | B13: 1104 | C13: 8 | D13: 2 | E13: 722 | F13: 47982803 | G13: 961 | H13: 14 | I13: 3 | J13: 735 | K13: 38103317
A14: 20BEK0009 | B14: 904 | C14: 9 | D14: 3 | E14: 543 | F14: 30435656 | G14: 809 | H14: 6 | I14: 2 | J14: 574 | K14: 18857266
A15: 20BEK0010 | B15: 1608 | C15: 24 | D15: 2 | E15: 1119 | F15: 51744158 | G15: 1608 | H15: 17 | I15: 1 | J15: 1043 | K15: 34570424
A16: 20BEK0011 | B16: 1274 | C16: 3 | D16: 2 | E16: 1037 | F16: 35227329 | G16: 1236 | H16: 7 | I16: 2 | J16: 1030 | K16: 24304103
A17: 20BEK0012 | B17: 996 | C17: 10 | D17: 1 | E17: 774 | F17: 35910747 | G17: 1049 | H17: 8 | I17: 1 | J17: 776 | K17: 24475514
... A90: 20BEK0094 | B90: 525 | C90: 2 | D90: 1 | E90: 145 | F90: 7090109.9 | G90: 588 | H90: 2 | I90: 1 | J90: 269 | K90: 1276708.3
A91: 20MPW0001 | B91: 2980 | C91: 11 | D91: 4 | E91: 1627 | F91: 1.1037485e+08
A92: 20MPW0002 | B92: 1008 | C92: 10 | D92: 1 | E92: 611 | F92: 41813047
A93: 20MPW0003 | B93: 1694 | C93: 9 | D93: 2 | E93: 885 | F93: 53218904
A94: 20MPW0004 | B94: 824 | C94: 2 | D94: 1 | E94: 541 | F94: 23105427
A95: 20MPW0005 | B95: 662 | C95: 6 | D95: 2 | E95: 425 | F95: 24486976
A96: 20MPW0006 | B96: 1587 | C96: 7 | D96: 4 | E96: 897 | F96: 27991328
A97: 20MPW0007 | B97: 1560 | C97: 28 | D97: 5 | E97: 405 | F97: 45023355
A98: 20MPW0008 | B98: 911 | C98: 8 | D98: 2 | E98: 624 | F98: 20747613
A99: 20MPW0009 | B99: 932 | C99: 6 | D99: 2 | E99: 394 | F99: 21405079
A100: 20MPW0010 | B100: 727 | C100: 10 | D100: 2 | E100: 435 | F100: 17561538
A101: 20MPW0011 | B101: 1450 | C101: 9 | D101: 2 | E101: 854 | F101: 29478217
A102: 20MPW0012 | B102: 1284 | C102: 18 | D102: 5 | E102: 764 | F102: 31826120
... A171: 20MPW0089 | B171: 3335 | C171: 45 | D171: 9 | E171: 1685 | F171: 83774045
A172: 20SBS0001 | B172: 1315 | C172: 12 | D172: 2 | E172: 628 | F172: 30694723 | G172: 1307 | H172: 11 | I172: 2 | J172: 610 | K172: 24391315
A173: 20SBS0002 | B173: 376 | C173: 0 | D173: 0 | E173: 19 | F173: 44034.957
A174: 20SBS0003 | B174: 1486 | C174: 17 | D174: 2 | E174: 881 | F174: 60988641 | G174: 1549 | H174: 15 | I174: 3 | J174: 927 | K174: 49149591
A175: 20SBS0004 | B175: 1577 | C175: 21 | D175: 6 | E175: 1010 | F175: 57425695 | G175: 1564 | H175: 12 | I175: 6 | J175: 1024 | K175: 35728521
A176: 20SBS0005 | B176: 1602 | C176: 42 | D176: 7 | E176: 1000 | F176: 35721656 | G176: 1654 | H176: 58 | I176: 5 | J176: 1106 | K176: 21676177
A177: 20SBS0006 | B177: 2606 | C177: 174 | D177: 4 | E177: 1415 | F177: 56726301 | G177: 2307 | H177: 56 | I177: 4 | J177: 1337 | K177: 26476963
A178: 20SBS0007 | B178: 2490 | C178: 91 | D178: 4 | E178: 1496 | F178: 70279339 | G178: 2736 | H178: 50 | I178: 6 | J178: 1963 | K178: 61221867
A179: 20SBS0008 | B179: 2238 | C179: 38 | D179: 4 | E179: 1595 | F179: 71608966 | G179: 1963 | H179: 22 | I179: 5 | J179: 1377 | K179: 47324365
A180: 20SBS0009 | B180: 821 | C180: 13 | D180: 5 | E180: 568 | F180: 45117663 | G180: 844 | H180: 10 | I180: 4 | J180: 594 | K180: 35915079
A181: 20SBS0010 | B181: 2389 | C181: 47 | D181: 6 | E181: 1606 | F181: 50214054 | G181: 2677 | H181: 152 | I181: 6 | J181: 1618 | K181: 30558338
A182: 20SBS0011 | B182: 1626 | C182: 17 | D182: 2 | E182: 978 | F182: 43507193 | G182: 1593 | H182: 16 | I182: 3 | J182: 1046 | K182: 25996206
...
